Workbook

Sheet EL_DEL_CD2_JO_
A1: DIALER MIS | AZ1: Dashboard Measurements | BD1: System Efficiency | BK1: Contact Rates | BP1: Contact Termcodes | BV1: Agent Hour Statistics | CC1: Average Call time Statistics
A2: Date | B2: Day | C2: Total Accounts | D2: Accounts Excluded | E2: Accounts Scheduled | F2: Accounts Called | G2: Dials | H2: Actual Dialer Dials | I2: Answers | J2: Connects | K2: Make Calls | L2: Aborts | M2: DROP | N2: PTP | O2: PAD | P2: OTP | Q2: DISP | R2: WN | S2: NC | T2: AU | U2: VOML | V2: CT | W2: TC | X2: EWS | Y2: WS | Z2: DS | AA2: BCTP | AB2: DPTP | AC2: WH | AD2: LB | AE2: TCBL | AF2: TPC | AG2: RTP | AH2: CBL | AI2: TOTAL CALLS | AJ2: TOTAL Contacts | AK2: TOTAL Promises | AL2: Logged in Time | AM2: Not Ready Time | AN2: Time On System | AO2: Idle Time | AP2: Preview Time | AQ2: Wrap Time | AR2: Talk Time | AS2: Agent Hours | AT2: Cur_Bal | AU2: PTP Value | AV2: Total PTP Value | AW2: Count Of Agents | AX2: Average TOS | AZ2: Completion Rate | BA2: Penetration | BB2: Contact Rate | BD2: Answer Rate | BE2: Connect Rate | BF2: Abort / Answer Rate | BG2: Idle Rate | BH2: Make Call Rate | BI2: Wrap Rate | BK2: Contact / Download | BL2: Contact / Accounts called | BM2: Contact / Dial | BN2: Contact / Connect | BP2: PTP Rate | BQ2: Pick-Up Rate | BR2: PTP+PAD rate | BS2: CallBack Rate | BT2: LB Rate | BV2: Accounts per Hour | BW2: Dials per Hour | BX2: Connects per Hour | BY2: Make Call per Hour | BZ2: Contacts per Hour | CA2: Promises per Hour | CC2: AHT | CD2: Talk | CE2: Wrap | CF2: Idle | CG2: Preview
AX3: Count Of Agents
A4: 46296 | B4: =+TEXT(A4,"DDD") -> Thu | AX4: =IFERROR(AN4/AW4,"-") -> - | AZ4: =IF(E4>0,F4/E4,"") | BA4: =+IF(E4>0,G4/E4,"") | BB4: =+IF(E4>0,AJ4/E4,"") | BD4: =+IF(G4>0,I4/G4,"") | BE4: =+IF(G4>0,J4/G4,"") | BF4: =+IF(I4>0,L4/I4,"") | BG4: =+IF(SUM(AO4:AR4)>0,AO4/AN4,"") | BH4: =+IF(G4>0,K4/G4,"") | BI4: =+IF(SUM(AO4:AR4)>0,AQ4/AN4,"") | BK4: =+IF(E4>0,(AJ4/E4),"") | BL4: =+IF(E4>0,(AJ4/F4),"") | BM4: =+IF(E4>0,(AJ4/G4),"") | BN4: =+IF(E4>0,(AJ4/J4),"") | BP4: =IF(AJ4>0,(N4/AJ4),"") | BQ4: 0 | BR4: =IF(AJ4>0,(AK4/AJ4),"") | BS4: =IF(AJ4>0,(AK4/AJ4),"") | BT4: =IF(J4>0,AD4/J4,"") | BV4: =IF(AN4>0,(E4/AN4),"") | BW4: =IF(AN4>0,(G4/AN4),"") | BX4: =IF(AN4>0,(J4/AN4),"") | BY4: =IF(AN4>0,(K4/AN4),"") | BZ4: =IF(AN4>0,(AJ4/AN4),"") | CA4: =IF(AN4>0,(AK4/AN4),"") | CC4: =IFERROR(((AN4-AO4)*3600)/J4,"-") -> - | CD4: =IFERROR((AR4*3600)/J4,"-") -> - | CE4: =IFERROR((AQ4*3600)/J4,"-") -> - | CF4: =IFERROR((AO4*3600)/J4,"-") -> - | CG4: =IFERROR((AP4*3600)/J4,"-") -> -
A5: =+A4+1 -> 46297 | B5: =+TEXT(A5,"DDD") -> Fri | AX5: =IFERROR(AN5/AW5,"-") -> - | AZ5: =IF(E5>0,F5/E5,"") | BA5: =+IF(E5>0,G5/E5,"") | BB5: =+IF(E5>0,AJ5/E5,"") | BD5: =+IF(G5>0,I5/G5,"") | BE5: =+IF(G5>0,J5/G5,"") | BF5: =+IF(I5>0,L5/I5,"") | BG5: =+IF(SUM(AO5:AR5)>0,AO5/AN5,"") | BH5: =+IF(G5>0,K5/G5,"") | BI5: =+IF(SUM(AO5:AR5)>0,AQ5/AN5,"") | BK5: =+IF(E5>0,(AJ5/E5),"") | BL5: =+IF(E5>0,(AJ5/F5),"") | BM5: =+IF(E5>0,(AJ5/G5),"") | BN5: =+IF(E5>0,(AJ5/J5),"") | BP5: =IF(AJ5>0,(N5/AJ5),"") | BQ5: 0 | BR5: =IF(AJ5>0,(AK5/AJ5),"") | BS5: =IF(AJ5>0,(AK5/AJ5),"") | BT5: =IF(J5>0,AD5/J5,"") | BV5: =IF(AN5>0,(E5/AN5),"") | BW5: =IF(AN5>0,(G5/AN5),"") | BX5: =IF(AN5>0,(J5/AN5),"") | BY5: =IF(AN5>0,(K5/AN5),"") | BZ5: =IF(AN5>0,(AJ5/AN5),"") | CA5: =IF(AN5>0,(AK5/AN5),"") | CC5: =IFERROR(((AN5-AO5)*3600)/J5,"-") -> - | CD5: =IFERROR((AR5*3600)/J5,"-") -> - | CE5: =IFERROR((AQ5*3600)/J5,"-") -> - | CF5: =IFERROR((AO5*3600)/J5,"-") -> - | CG5: =IFERROR((AP5*3600)/J5,"-") -> -
A6: =+A5+1 -> 46298 | B6: =+TEXT(A6,"DDD") -> Sat | AX6: =IFERROR(AN6/AW6,"-") -> - | AZ6: =IF(E6>0,F6/E6,"") | BA6: =+IF(E6>0,G6/E6,"") | BB6: =+IF(E6>0,AJ6/E6,"") | BD6: =+IF(G6>0,I6/G6,"") | BE6: =+IF(G6>0,J6/G6,"") | BF6: =+IF(I6>0,L6/I6,"") | BG6: =+IF(SUM(AO6:AR6)>0,AO6/AN6,"") | BH6: =+IF(G6>0,K6/G6,"") | BI6: =+IF(SUM(AO6:AR6)>0,AQ6/AN6,"") | BK6: =+IF(E6>0,(AJ6/E6),"") | BL6: =+IF(E6>0,(AJ6/F6),"") | BM6: =+IF(E6>0,(AJ6/G6),"") | BN6: =+IF(E6>0,(AJ6/J6),"") | BP6: =IF(AJ6>0,(N6/AJ6),"") | BQ6: 0 | BR6: =IF(AJ6>0,(AK6/AJ6),"") | BS6: =IF(AJ6>0,(AK6/AJ6),"") | BT6: =IF(J6>0,AD6/J6,"") | BV6: =IF(AN6>0,(E6/AN6),"") | BW6: =IF(AN6>0,(G6/AN6),"") | BX6: =IF(AN6>0,(J6/AN6),"") | BY6: =IF(AN6>0,(K6/AN6),"") | BZ6: =IF(AN6>0,(AJ6/AN6),"") | CA6: =IF(AN6>0,(AK6/AN6),"") | CC6: =IFERROR(((AN6-AO6)*3600)/J6,"-") -> - | CD6: =IFERROR((AR6*3600)/J6,"-") -> - | CE6: =IFERROR((AQ6*3600)/J6,"-") -> - | CF6: =IFERROR((AO6*3600)/J6,"-") -> - | CG6: =IFERROR((AP6*3600)/J6,"-") -> -
A7: =+A6+1 -> 46299 | B7: =+TEXT(A7,"DDD") -> Sun | AX7: =IFERROR(AN7/AW7,"-") -> - | AZ7: =IF(E7>0,F7/E7,"") | BA7: =+IF(E7>0,G7/E7,"") | BB7: =+IF(E7>0,AJ7/E7,"") | BD7: =+IF(G7>0,I7/G7,"") | BE7: =+IF(G7>0,J7/G7,"") | BF7: =+IF(I7>0,L7/I7,"") | BG7: =+IF(SUM(AO7:AR7)>0,AO7/AN7,"") | BH7: =+IF(G7>0,K7/G7,"") | BI7: =+IF(SUM(AO7:AR7)>0,AQ7/AN7,"") | BK7: =+IF(E7>0,(AJ7/E7),"") | BL7: =+IF(E7>0,(AJ7/F7),"") | BM7: =+IF(E7>0,(AJ7/G7),"") | BN7: =+IF(E7>0,(AJ7/J7),"") | BP7: =IF(AJ7>0,(N7/AJ7),"") | BQ7: 0 | BR7: =IF(AJ7>0,(AK7/AJ7),"") | BS7: =IF(AJ7>0,(AK7/AJ7),"") | BT7: =IF(J7>0,AD7/J7,"") | BV7: =IF(AN7>0,(E7/AN7),"") | BW7: =IF(AN7>0,(G7/AN7),"") | BX7: =IF(AN7>0,(J7/AN7),"") | BY7: =IF(AN7>0,(K7/AN7),"") | BZ7: =IF(AN7>0,(AJ7/AN7),"") | CA7: =IF(AN7>0,(AK7/AN7),"") | CC7: =IFERROR(((AN7-AO7)*3600)/J7,"-") -> - | CD7: =IFERROR((AR7*3600)/J7,"-") -> - | CE7: =IFERROR((AQ7*3600)/J7,"-") -> - | CF7: =IFERROR((AO7*3600)/J7,"-") -> - | CG7: =IFERROR((AP7*3600)/J7,"-") -> -
A8: =+A7+1 -> 46300 | B8: =+TEXT(A8,"DDD") -> Mon | AX8: =IFERROR(AN8/AW8,"-") -> - | AZ8: =IF(E8>0,F8/E8,"") | BA8: =+IF(E8>0,G8/E8,"") | BB8: =+IF(E8>0,AJ8/E8,"") | BD8: =+IF(G8>0,I8/G8,"") | BE8: =+IF(G8>0,J8/G8,"") | BF8: =+IF(I8>0,L8/I8,"") | BG8: =+IF(SUM(AO8:AR8)>0,AO8/AN8,"") | BH8: =+IF(G8>0,K8/G8,"") | BI8: =+IF(SUM(AO8:AR8)>0,AQ8/AN8,"") | BK8: =+IF(E8>0,(AJ8/E8),"") | BL8: =+IF(E8>0,(AJ8/F8),"") | BM8: =+IF(E8>0,(AJ8/G8),"") | BN8: =+IF(E8>0,(AJ8/J8),"") | BP8: =IF(AJ8>0,(N8/AJ8),"") | BQ8: 0 | BR8: =IF(AJ8>0,(AK8/AJ8),"") | BS8: =IF(AJ8>0,(AK8/AJ8),"") | BT8: =IF(J8>0,AD8/J8,"") | BV8: =IF(AN8>0,(E8/AN8),"") | BW8: =IF(AN8>0,(G8/AN8),"") | BX8: =IF(AN8>0,(J8/AN8),"") | BY8: =IF(AN8>0,(K8/AN8),"") | BZ8: =IF(AN8>0,(AJ8/AN8),"") | CA8: =IF(AN8>0,(AK8/AN8),"") | CC8: =IFERROR(((AN8-AO8)*3600)/J8,"-") -> - | CD8: =IFERROR((AR8*3600)/J8,"-") -> - | CE8: =IFERROR((AQ8*3600)/J8,"-") -> - | CF8: =IFERROR((AO8*3600)/J8,"-") -> - | CG8: =IFERROR((AP8*3600)/J8,"-") -> -
A9: =+A8+1 -> 46301 | B9: =+TEXT(A9,"DDD") -> Tue | AX9: =IFERROR(AN9/AW9,"-") -> - | AZ9: =IF(E9>0,F9/E9,"") | BA9: =+IF(E9>0,G9/E9,"") | BB9: =+IF(E9>0,AJ9/E9,"") | BD9: =+IF(G9>0,I9/G9,"") | BE9: =+IF(G9>0,J9/G9,"") | BF9: =+IF(I9>0,L9/I9,"") | BG9: =+IF(SUM(AO9:AR9)>0,AO9/AN9,"") | BH9: =+IF(G9>0,K9/G9,"") | BI9: =+IF(SUM(AO9:AR9)>0,AQ9/AN9,"") | BK9: =+IF(E9>0,(AJ9/E9),"") | BL9: =+IF(E9>0,(AJ9/F9),"") | BM9: =+IF(E9>0,(AJ9/G9),"") | BN9: =+IF(E9>0,(AJ9/J9),"") | BP9: =IF(AJ9>0,(N9/AJ9),"") | BQ9: 0 | BR9: =IF(AJ9>0,(AK9/AJ9),"") | BS9: =IF(AJ9>0,(AK9/AJ9),"") | BT9: =IF(J9>0,AD9/J9,"") | BV9: =IF(AN9>0,(E9/AN9),"") | BW9: =IF(AN9>0,(G9/AN9),"") | BX9: =IF(AN9>0,(J9/AN9),"") | BY9: =IF(AN9>0,(K9/AN9),"") | BZ9: =IF(AN9>0,(AJ9/AN9),"") | CA9: =IF(AN9>0,(AK9/AN9),"") | CC9: =IFERROR(((AN9-AO9)*3600)/J9,"-") -> - | CD9: =IFERROR((AR9*3600)/J9,"-") -> - | CE9: =IFERROR((AQ9*3600)/J9,"-") -> - | CF9: =IFERROR((AO9*3600)/J9,"-") -> - | CG9: =IFERROR((AP9*3600)/J9,"-") -> -
A10: =+A9+1 -> 46302 | B10: =+TEXT(A10,"DDD") -> Wed | AX10: =IFERROR(AN10/AW10,"-") -> - | AZ10: =IF(E10>0,F10/E10,"") | BA10: =+IF(E10>0,G10/E10,"") | BB10: =+IF(E10>0,AJ10/E10,"") | BD10: =+IF(G10>0,I10/G10,"") | BE10: =+IF(G10>0,J10/G10,"") | BF10: =+IF(I10>0,L10/I10,"") | BG10: =+IF(SUM(AO10:AR10)>0,AO10/AN10,"") | BH10: =+IF(G10>0,K10/G10,"") | BI10: =+IF(SUM(AO10:AR10)>0,AQ10/AN10,"") | BK10: =+IF(E10>0,(AJ10/E10),"") | BL10: =+IF(E10>0,(AJ10/F10),"") | BM10: =+IF(E10>0,(AJ10/G10),"") | BN10: =+IF(E10>0,(AJ10/J10),"") | BP10: =IF(AJ10>0,(N10/AJ10),"") | BQ10: 0 | BR10: =IF(AJ10>0,(AK10/AJ10),"") | BS10: =IF(AJ10>0,(AK10/AJ10),"") | BT10: =IF(J10>0,AD10/J10,"") | BV10: =IF(AN10>0,(E10/AN10),"") | BW10: =IF(AN10>0,(G10/AN10),"") | BX10: =IF(AN10>0,(J10/AN10),"") | BY10: =IF(AN10>0,(K10/AN10),"") | BZ10: =IF(AN10>0,(AJ10/AN10),"") | CA10: =IF(AN10>0,(AK10/AN10),"") | CC10: =IFERROR(((AN10-AO10)*3600)/J10,"-") -> - | CD10: =IFERROR((AR10*3600)/J10,"-") -> - | CE10: =IFERROR((AQ10*3600)/J10,"-") -> - | CF10: =IFERROR((AO10*3600)/J10,"-") -> - | CG10: =IFERROR((AP10*3600)/J10,"-") -> -
A11: =+A10+1 -> 46303 | B11: =+TEXT(A11,"DDD") -> Thu | AX11: =IFERROR(AN11/AW11,"-") -> - | AZ11: =IF(E11>0,F11/E11,"") | BA11: =+IF(E11>0,G11/E11,"") | BB11: =+IF(E11>0,AJ11/E11,"") | BD11: =+IF(G11>0,I11/G11,"") | BE11: =+IF(G11>0,J11/G11,"") | BF11: =+IF(I11>0,L11/I11,"") | BG11: =+IF(SUM(AO11:AR11)>0,AO11/AN11,"") | BH11: =+IF(G11>0,K11/G11,"") | BI11: =+IF(SUM(AO11:AR11)>0,AQ11/AN11,"") | BK11: =+IF(E11>0,(AJ11/E11),"") | BL11: =+IF(E11>0,(AJ11/F11),"") | BM11: =+IF(E11>0,(AJ11/G11),"") | BN11: =+IF(E11>0,(AJ11/J11),"") | BP11: =IF(AJ11>0,(N11/AJ11),"") | BQ11: 0 | BR11: =IF(AJ11>0,(AK11/AJ11),"") | BS11: =IF(AJ11>0,(AK11/AJ11),"") | BT11: =IF(J11>0,AD11/J11,"") | BV11: =IF(AN11>0,(E11/AN11),"") | BW11: =IF(AN11>0,(G11/AN11),"") | BX11: =IF(AN11>0,(J11/AN11),"") | BY11: =IF(AN11>0,(K11/AN11),"") | BZ11: =IF(AN11>0,(AJ11/AN11),"") | CA11: =IF(AN11>0,(AK11/AN11),"") | CC11: =IFERROR(((AN11-AO11)*3600)/J11,"-") -> - | CD11: =IFERROR((AR11*3600)/J11,"-") -> - | CE11: =IFERROR((AQ11*3600)/J11,"-") -> - | CF11: =IFERROR((AO11*3600)/J11,"-") -> - | CG11: =IFERROR((AP11*3600)/J11,"-") -> -
A12: =+A11+1 -> 46304 | B12: =+TEXT(A12,"DDD") -> Fri | AX12: =IFERROR(AN12/AW12,"-") -> - | AZ12: =IF(E12>0,F12/E12,"") | BA12: =+IF(E12>0,G12/E12,"") | BB12: =+IF(E12>0,AJ12/E12,"") | BD12: =+IF(G12>0,I12/G12,"") | BE12: =+IF(G12>0,J12/G12,"") | BF12: =+IF(I12>0,L12/I12,"") | BG12: =+IF(SUM(AO12:AR12)>0,AO12/AN12,"") | BH12: =+IF(G12>0,K12/G12,"") | BI12: =+IF(SUM(AO12:AR12)>0,AQ12/AN12,"") | BK12: =+IF(E12>0,(AJ12/E12),"") | BL12: =+IF(E12>0,(AJ12/F12),"") | BM12: =+IF(E12>0,(AJ12/G12),"") | BN12: =+IF(E12>0,(AJ12/J12),"") | BP12: =IF(AJ12>0,(N12/AJ12),"") | BQ12: 0 | BR12: =IF(AJ12>0,(AK12/AJ12),"") | BS12: =IF(AJ12>0,(AK12/AJ12),"") | BT12: =IF(J12>0,AD12/J12,"") | BV12: =IF(AN12>0,(E12/AN12),"") | BW12: =IF(AN12>0,(G12/AN12),"") | BX12: =IF(AN12>0,(J12/AN12),"") | BY12: =IF(AN12>0,(K12/AN12),"") | BZ12: =IF(AN12>0,(AJ12/AN12),"") | CA12: =IF(AN12>0,(AK12/AN12),"") | CC12: =IFERROR(((AN12-AO12)*3600)/J12,"-") -> - | CD12: =IFERROR((AR12*3600)/J12,"-") -> - | CE12: =IFERROR((AQ12*3600)/J12,"-") -> - | CF12: =IFERROR((AO12*3600)/J12,"-") -> - | CG12: =IFERROR((AP12*3600)/J12,"-") -> -
A13: =+A12+1 -> 46305 | B13: =+TEXT(A13,"DDD") -> Sat | AX13: =IFERROR(AN13/AW13,"-") -> - | AZ13: =IF(E13>0,F13/E13,"") | BA13: =+IF(E13>0,G13/E13,"") | BB13: =+IF(E13>0,AJ13/E13,"") | BD13: =+IF(G13>0,I13/G13,"") | BE13: =+IF(G13>0,J13/G13,"") | BF13: =+IF(I13>0,L13/I13,"") | BG13: =+IF(SUM(AO13:AR13)>0,AO13/AN13,"") | BH13: =+IF(G13>0,K13/G13,"") | BI13: =+IF(SUM(AO13:AR13)>0,AQ13/AN13,"") | BK13: =+IF(E13>0,(AJ13/E13),"") | BL13: =+IF(E13>0,(AJ13/F13),"") | BM13: =+IF(E13>0,(AJ13/G13),"") | BN13: =+IF(E13>0,(AJ13/J13),"") | BP13: =IF(AJ13>0,(N13/AJ13),"") | BQ13: 0 | BR13: =IF(AJ13>0,(AK13/AJ13),"") | BS13: =IF(AJ13>0,(AK13/AJ13),"") | BT13: =IF(J13>0,AD13/J13,"") | BV13: =IF(AN13>0,(E13/AN13),"") | BW13: =IF(AN13>0,(G13/AN13),"") | BX13: =IF(AN13>0,(J13/AN13),"") | BY13: =IF(AN13>0,(K13/AN13),"") | BZ13: =IF(AN13>0,(AJ13/AN13),"") | CA13: =IF(AN13>0,(AK13/AN13),"") | CC13: =IFERROR(((AN13-AO13)*3600)/J13,"-") -> - | CD13: =IFERROR((AR13*3600)/J13,"-") -> - | CE13: =IFERROR((AQ13*3600)/J13,"-") -> - | CF13: =IFERROR((AO13*3600)/J13,"-") -> - | CG13: =IFERROR((AP13*3600)/J13,"-") -> -
A14: =+A13+1 -> 46306 | B14: =+TEXT(A14,"DDD") -> Sun | AX14: =IFERROR(AN14/AW14,"-") -> - | AZ14: =IF(E14>0,F14/E14,"") | BA14: =+IF(E14>0,G14/E14,"") | BB14: =+IF(E14>0,AJ14/E14,"") | BD14: =+IF(G14>0,J17/G14,"") | BE14: =+IF(G14>0,J14/G14,"") | BF14: =+IF(J17>0,L14/J17,"") | BG14: =+IF(SUM(AO14:AR14)>0,AO14/AN14,"") | BH14: =+IF(G14>0,K14/G14,"") | BI14: =+IF(SUM(AO14:AR14)>0,AQ14/AN14,"") | BK14: =+IF(E14>0,(AJ14/E14),"") | BL14: =+IF(E14>0,(AJ14/F14),"") | BM14: =+IF(E14>0,(AJ14/G14),"") | BN14: =+IF(E14>0,(AJ14/J14),"") | BP14: =IF(AJ14>0,(N14/AJ14),"") | BQ14: 0 | BR14: =IF(AJ14>0,(AK14/AJ14),"") | BS14: =IF(AJ14>0,(AK14/AJ14),"") | BT14: =IF(J14>0,AD14/J14,"") | BV14: =IF(AN14>0,(E14/AN14),"") | BW14: =IF(AN14>0,(G14/AN14),"") | BX14: =IF(AN14>0,(J14/AN14),"") | BY14: =IF(AN14>0,(K14/AN14),"") | BZ14: =IF(AN14>0,(AJ14/AN14),"") | CA14: =IF(AN14>0,(AK14/AN14),"") | CC14: =IFERROR(((AN14-AO14)*3600)/J14,"-") -> - | CD14: =IFERROR((AR14*3600)/J14,"-") -> - | CE14: =IFERROR((AQ14*3600)/J14,"-") -> - | CF14: =IFERROR((AO14*3600)/J14,"-") -> - | CG14: =IFERROR((AP14*3600)/J14,"-") -> -
A15: =+A14+1 -> 46307 | B15: =+TEXT(A15,"DDD") -> Mon | AX15: =IFERROR(AN15/AW15,"-") -> - | AZ15: =IF(E15>0,F15/E15,"") | BA15: =+IF(E15>0,G15/E15,"") | BB15: =+IF(E15>0,AJ15/E15,"") | BD15: =+IF(G15>0,I15/G15,"") | BE15: =+IF(G15>0,J15/G15,"") | BF15: =+IF(I15>0,L15/I15,"") | BG15: =+IF(SUM(AO15:AR15)>0,AO15/AN15,"") | BH15: =+IF(G15>0,K15/G15,"") | BI15: =+IF(SUM(AO15:AR15)>0,AQ15/AN15,"") | BK15: =+IF(E15>0,(AJ15/E15),"") | BL15: =+IF(E15>0,(AJ15/F15),"") | BM15: =+IF(E15>0,(AJ15/G15),"") | BN15: =+IF(E15>0,(AJ15/J15),"") | BP15: =IF(AJ15>0,(N15/AJ15),"") | BQ15: 0 | BR15: =IF(AJ15>0,(AK15/AJ15),"") | BS15: =IF(AJ15>0,(AK15/AJ15),"") | BT15: =IF(J15>0,AD15/J15,"") | BV15: =IF(AN15>0,(E15/AN15),"") | BW15: =IF(AN15>0,(G15/AN15),"") | BX15: =IF(AN15>0,(J15/AN15),"") | BY15: =IF(AN15>0,(K15/AN15),"") | BZ15: =IF(AN15>0,(AJ15/AN15),"") | CA15: =IF(AN15>0,(AK15/AN15),"") | CC15: =IFERROR(((AN15-AO15)*3600)/J15,"-") -> - | CD15: =IFERROR((AR15*3600)/J15,"-") -> - | CE15: =IFERROR((AQ15*3600)/J15,"-") -> - | CF15: =IFERROR((AO15*3600)/J15,"-") -> - | CG15: =IFERROR((AP15*3600)/J15,"-") -> -
A16: =+A15+1 -> 46308 | B16: =+TEXT(A16,"DDD") -> Tue | AX16: =IFERROR(AN16/AW16,"-") -> - | AZ16: =IF(E16>0,F16/E16,"") | BA16: =+IF(E16>0,G16/E16,"") | BB16: =+IF(E16>0,AJ16/E16,"") | BD16: =+IF(G16>0,I16/G16,"") | BE16: =+IF(G16>0,J16/G16,"") | BF16: =+IF(I16>0,L16/I16,"") | BG16: =+IF(SUM(AO16:AR16)>0,AO16/AN16,"") | BH16: =+IF(G16>0,K16/G16,"") | BI16: =+IF(SUM(AO16:AR16)>0,AQ16/AN16,"") | BK16: =+IF(E16>0,(AJ16/E16),"") | BL16: =+IF(E16>0,(AJ16/F16),"") | BM16: =+IF(E16>0,(AJ16/G16),"") | BN16: =+IF(E16>0,(AJ16/J16),"") | BP16: =IF(AJ16>0,(N16/AJ16),"") | BQ16: 0 | BR16: =IF(AJ16>0,(AK16/AJ16),"") | BS16: =IF(AJ16>0,(AK16/AJ16),"") | BT16: =IF(J16>0,AD16/J16,"") | BV16: =IF(AN16>0,(E16/AN16),"") | BW16: =IF(AN16>0,(G16/AN16),"") | BX16: =IF(AN16>0,(J16/AN16),"") | BY16: =IF(AN16>0,(K16/AN16),"") | BZ16: =IF(AN16>0,(AJ16/AN16),"") | CA16: =IF(AN16>0,(AK16/AN16),"") | CC16: =IFERROR(((AN16-AO16)*3600)/J16,"-") -> - | CD16: =IFERROR((AR16*3600)/J16,"-") -> - | CE16: =IFERROR((AQ16*3600)/J16,"-") -> - | CF16: =IFERROR((AO16*3600)/J16,"-") -> - | CG16: =IFERROR((AP16*3600)/J16,"-") -> -
A17: =+A16+1 -> 46309 | B17: =+TEXT(A17,"DDD") -> Wed | AX17: =IFERROR(AN17/AW17,"-") -> - | AZ17: =IF(E17>0,F17/E17,"") | BA17: =+IF(E17>0,G17/E17,"") | BB17: =+IF(E17>0,AJ17/E17,"") | BD17: =+IF(G17>0,I17/G17,"") | BE17: =+IF(G17>0,#REF!/G17,"") | BF17: =+IF(I17>0,L17/I17,"") | BG17: =+IF(SUM(AO17:AR17)>0,AO17/AN17,"") | BH17: =+IF(G17>0,K17/G17,"") | BI17: =+IF(SUM(AO17:AR17)>0,AQ17/AN17,"") | BK17: =+IF(E17>0,(AJ17/E17),"") | BL17: =+IF(E17>0,(AJ17/F17),"") | BM17: =+IF(E17>0,(AJ17/G17),"") | BN17: =+IF(E17>0,(AJ17/J17),"") | BP17: =IF(AJ17>0,(N17/AJ17),"") | BQ17: 0 | BR17: =IF(AJ17>0,(AK17/AJ17),"") | BS17: =IF(AJ17>0,(AK17/AJ17),"") | BT17: =IF(J17>0,AD17/J17,"") | BV17: =IF(AN17>0,(E17/AN17),"") | BW17: =IF(AN17>0,(G17/AN17),"") | BX17: =IF(AN17>0,(J17/AN17),"") | BY17: =IF(AN17>0,(K17/AN17),"") | BZ17: =IF(AN17>0,(AJ17/AN17),"") | CA17: =IF(AN17>0,(AK17/AN17),"") | CC17: =IFERROR(((AN17-AO17)*3600)/J17,"-") -> - | CD17: =IFERROR((AR17*3600)/J17,"-") -> - | CE17: =IFERROR((AQ17*3600)/J17,"-") -> - | CF17: =IFERROR((AO17*3600)/J17,"-") -> - | CG17: =IFERROR((AP17*3600)/J17,"-") -> -
A18: =+A17+1 -> 46310 | B18: =+TEXT(A18,"DDD") -> Thu | AX18: =IFERROR(AN18/AW18,"-") -> - | AZ18: =IF(E18>0,F18/E18,"") | BA18: =+IF(E18>0,G18/E18,"") | BB18: =+IF(E18>0,AJ18/E18,"") | BD18: =+IF(G18>0,I18/G18,"") | BE18: =+IF(G18>0,J18/G18,"") | BF18: =+IF(I18>0,L18/I18,"") | BG18: =+IF(SUM(AO18:AR18)>0,AO18/AN18,"") | BH18: =+IF(G18>0,K18/G18,"") | BI18: =+IF(SUM(AO18:AR18)>0,AQ18/AN18,"") | BK18: =+IF(E18>0,(AJ18/E18),"") | BL18: =+IF(E18>0,(AJ18/F18),"") | BM18: =+IF(E18>0,(AJ18/G18),"") | BN18: =+IF(E18>0,(AJ18/J18),"") | BP18: =IF(AJ18>0,(N18/AJ18),"") | BQ18: 0 | BR18: =IF(AJ18>0,(AK18/AJ18),"") | BS18: =IF(AJ18>0,(AK18/AJ18),"") | BT18: =IF(J18>0,AD18/J18,"") | BV18: =IF(AN18>0,(E18/AN18),"") | BW18: =IF(AN18>0,(G18/AN18),"") | BX18: =IF(AN18>0,(J18/AN18),"") | BY18: =IF(AN18>0,(K18/AN18),"") | BZ18: =IF(AN18>0,(AJ18/AN18),"") | CA18: =IF(AN18>0,(AK18/AN18),"") | CC18: =IFERROR(((AN18-AO18)*3600)/J18,"-") -> - | CD18: =IFERROR((AR18*3600)/J18,"-") -> - | CE18: =IFERROR((AQ18*3600)/J18,"-") -> - | CF18: =IFERROR((AO18*3600)/J18,"-") -> - | CG18: =IFERROR((AP18*3600)/J18,"-") -> -
A19: =+A18+1 -> 46311 | B19: =+TEXT(A19,"DDD") -> Fri | AX19: =IFERROR(AN19/AW19,"-") -> - | AZ19: =IF(E19>0,F19/E19,"") | BA19: =+IF(E19>0,G19/E19,"") | BB19: =+IF(E19>0,AJ19/E19,"") | BD19: =+IF(G19>0,I19/G19,"") | BE19: =+IF(G19>0,J19/G19,"") | BF19: =+IF(I19>0,L19/I19,"") | BG19: =+IF(SUM(AO19:AR19)>0,AO19/AN19,"") | BH19: =+IF(G19>0,K19/G19,"") | BI19: =+IF(SUM(AO19:AR19)>0,AQ19/AN19,"") | BK19: =+IF(E19>0,(AJ19/E19),"") | BL19: =+IF(E19>0,(AJ19/F19),"") | BM19: =+IF(E19>0,(AJ19/G19),"") | BN19: =+IF(E19>0,(AJ19/J19),"") | BP19: =IF(AJ19>0,(N19/AJ19),"") | BQ19: 0 | BR19: =IF(AJ19>0,(AK19/AJ19),"") | BS19: =IF(AJ19>0,(AK19/AJ19),"") | BT19: =IF(J19>0,AD19/J19,"") | BV19: =IF(AN19>0,(E19/AN19),"") | BW19: =IF(AN19>0,(G19/AN19),"") | BX19: =IF(AN19>0,(J19/AN19),"") | BY19: =IF(AN19>0,(K19/AN19),"") | BZ19: =IF(AN19>0,(AJ19/AN19),"") | CA19: =IF(AN19>0,(AK19/AN19),"") | CC19: =IFERROR(((AN19-AO19)*3600)/J19,"-") -> - | CD19: =IFERROR((AR19*3600)/J19,"-") -> - | CE19: =IFERROR((AQ19*3600)/J19,"-") -> - | CF19: =IFERROR((AO19*3600)/J19,"-") -> - | CG19: =IFERROR((AP19*3600)/J19,"-") -> -
A20: =+A19+1 -> 46312 | B20: =+TEXT(A20,"DDD") -> Sat | AX20: =IFERROR(AN20/AW20,"-") -> - | AZ20: =IF(E20>0,F20/E20,"") | BA20: =+IF(E20>0,G20/E20,"") | BB20: =+IF(E20>0,AJ20/E20,"") | BD20: =+IF(G20>0,I20/G20,"") | BE20: =+IF(G20>0,J20/G20,"") | BF20: =+IF(I20>0,L20/I20,"") | BG20: =+IF(SUM(AO20:AR20)>0,AO20/AN20,"") | BH20: =+IF(G20>0,K20/G20,"") | BI20: =+IF(SUM(AO20:AR20)>0,AQ20/AN20,"") | BK20: =+IF(E20>0,(AJ20/E20),"") | BL20: =+IF(E20>0,(AJ20/F20),"") | BM20: =+IF(E20>0,(AJ20/G20),"") | BN20: =+IF(E20>0,(AJ20/J20),"") | BP20: =IF(AJ20>0,(N20/AJ20),"") | BQ20: 0 | BR20: =IF(AJ20>0,(AK20/AJ20),"") | BS20: =IF(AJ20>0,(AK20/AJ20),"") | BT20: =IF(J20>0,AD20/J20,"") | BV20: =IF(AN20>0,(E20/AN20),"") | BW20: =IF(AN20>0,(G20/AN20),"") | BX20: =IF(AN20>0,(J20/AN20),"") | BY20: =IF(AN20>0,(K20/AN20),"") | BZ20: =IF(AN20>0,(AJ20/AN20),"") | CA20: =IF(AN20>0,(AK20/AN20),"") | CC20: =IFERROR(((AN20-AO20)*3600)/J20,"-") -> - | CD20: =IFERROR((AR20*3600)/J20,"-") -> - | CE20: =IFERROR((AQ20*3600)/J20,"-") -> - | CF20: =IFERROR((AO20*3600)/J20,"-") -> - | CG20: =IFERROR((AP20*3600)/J20,"-") -> -
A21: =+A20+1 -> 46313 | B21: =+TEXT(A21,"DDD") -> Sun | AX21: =IFERROR(AN21/AW21,"-") -> - | AZ21: =IF(E21>0,F21/E21,"") | BA21: =+IF(E21>0,G21/E21,"") | BB21: =+IF(E21>0,AJ21/E21,"") | BD21: =+IF(G21>0,I21/G21,"") | BE21: =+IF(G21>0,J21/G21,"") | BF21: =+IF(I21>0,L21/I21,"") | BG21: =+IF(SUM(AO21:AR21)>0,AO21/AN21,"") | BH21: =+IF(G21>0,K21/G21,"") | BI21: =+IF(SUM(AO21:AR21)>0,AQ21/AN21,"") | BK21: =+IF(E21>0,(AJ21/E21),"") | BL21: =+IF(E21>0,(AJ21/F21),"") | BM21: =+IF(E21>0,(AJ21/G21),"") | BN21: =+IF(E21>0,(AJ21/J21),"") | BP21: =IF(AJ21>0,(N21/AJ21),"") | BQ21: 0 | BR21: =IF(AJ21>0,(AK21/AJ21),"") | BS21: =IF(AJ21>0,(AK21/AJ21),"") | BT21: =IF(J21>0,AD21/J21,"") | BV21: =IF(AN21>0,(E21/AN21),"") | BW21: =IF(AN21>0,(G21/AN21),"") | BX21: =IF(AN21>0,(J21/AN21),"") | BY21: =IF(AN21>0,(K21/AN21),"") | BZ21: =IF(AN21>0,(AJ21/AN21),"") | CA21: =IF(AN21>0,(AK21/AN21),"") | CC21: =IFERROR(((AN21-AO21)*3600)/J21,"-") -> - | CD21: =IFERROR((AR21*3600)/J21,"-") -> - | CE21: =IFERROR((AQ21*3600)/J21,"-") -> - | CF21: =IFERROR((AO21*3600)/J21,"-") -> - | CG21: =IFERROR((AP21*3600)/J21,"-") -> -
A22: =+A21+1 -> 46314 | B22: =+TEXT(A22,"DDD") -> Mon | AX22: =IFERROR(AN22/AW22,"-") -> - | AZ22: =IF(E22>0,F22/E22,"") | BA22: =+IF(E22>0,G22/E22,"") | BB22: =+IF(E22>0,AJ22/E22,"") | BD22: =+IF(G22>0,I22/G22,"") | BE22: =+IF(G22>0,J22/G22,"") | BF22: =+IF(I22>0,L22/I22,"") | BG22: =+IF(SUM(AO22:AR22)>0,AO22/AN22,"") | BH22: =+IF(G22>0,K22/G22,"") | BI22: =+IF(SUM(AO22:AR22)>0,AQ22/AN22,"") | BK22: =+IF(E22>0,(AJ22/E22),"") | BL22: =+IF(E22>0,(AJ22/F22),"") | BM22: =+IF(E22>0,(AJ22/G22),"") | BN22: =+IF(E22>0,(AJ22/J22),"") | BP22: =IF(AJ22>0,(N22/AJ22),"") | BQ22: 0 | BR22: =IF(AJ22>0,(AK22/AJ22),"") | BS22: =IF(AJ22>0,(AK22/AJ22),"") | BT22: =IF(J22>0,AD22/J22,"") | BV22: =IF(AN22>0,(E22/AN22),"") | BW22: =IF(AN22>0,(G22/AN22),"") | BX22: =IF(AN22>0,(J22/AN22),"") | BY22: =IF(AN22>0,(K22/AN22),"") | BZ22: =IF(AN22>0,(AJ22/AN22),"") | CA22: =IF(AN22>0,(AK22/AN22),"") | CC22: =IFERROR(((AN22-AO22)*3600)/J22,"-") -> - | CD22: =IFERROR((AR22*3600)/J22,"-") -> - | CE22: =IFERROR((AQ22*3600)/J22,"-") -> - | CF22: =IFERROR((AO22*3600)/J22,"-") -> - | CG22: =IFERROR((AP22*3600)/J22,"-") -> -
A23: =+A22+1 -> 46315 | B23: =+TEXT(A23,"DDD") -> Tue | AX23: =IFERROR(AN23/AW23,"-") -> - | AZ23: =IF(E23>0,F23/E23,"") | BA23: =+IF(E23>0,G23/E23,"") | BB23: =+IF(E23>0,AJ23/E23,"") | BD23: =+IF(G23>0,I23/G23,"") | BE23: =+IF(G23>0,J23/G23,"") | BF23: =+IF(I23>0,L23/I23,"") | BG23: =+IF(SUM(AO23:AR23)>0,AO23/AN23,"") | BH23: =+IF(G23>0,K23/G23,"") | BI23: =+IF(SUM(AO23:AR23)>0,AQ23/AN23,"") | BK23: =+IF(E23>0,(AJ23/E23),"") | BL23: =+IF(E23>0,(AJ23/F23),"") | BM23: =+IF(E23>0,(AJ23/G23),"") | BN23: =+IF(E23>0,(AJ23/J23),"") | BP23: =IF(AJ23>0,(N23/AJ23),"") | BQ23: 0 | BR23: =IF(AJ23>0,(AK23/AJ23),"") | BS23: =IF(AJ23>0,(AK23/AJ23),"") | BT23: =IF(J23>0,AD23/J23,"") | BV23: =IF(AN23>0,(E23/AN23),"") | BW23: =IF(AN23>0,(G23/AN23),"") | BX23: =IF(AN23>0,(J23/AN23),"") | BY23: =IF(AN23>0,(K23/AN23),"") | BZ23: =IF(AN23>0,(AJ23/AN23),"") | CA23: =IF(AN23>0,(AK23/AN23),"") | CC23: =IFERROR(((AN23-AO23)*3600)/J23,"-") -> - | CD23: =IFERROR((AR23*3600)/J23,"-") -> - | CE23: =IFERROR((AQ23*3600)/J23,"-") -> - | CF23: =IFERROR((AO23*3600)/J23,"-") -> - | CG23: =IFERROR((AP23*3600)/J23,"-") -> -
A24: =+A23+1 -> 46316 | B24: =+TEXT(A24,"DDD") -> Wed | AX24: =IFERROR(AN24/AW24,"-") -> - | AZ24: =IF(E24>0,F24/E24,"") | BA24: =+IF(E24>0,G24/E24,"") | BB24: =+IF(E24>0,AJ24/E24,"") | BD24: =+IF(G24>0,I24/G24,"") | BE24: =+IF(G24>0,J24/G24,"") | BF24: =+IF(I24>0,L24/I24,"") | BG24: =+IF(SUM(AO24:AR24)>0,AO24/AN24,"") | BH24: =+IF(G24>0,K24/G24,"") | BI24: =+IF(SUM(AO24:AR24)>0,AQ24/AN24,"") | BK24: =+IF(E24>0,(AJ24/E24),"") | BL24: =+IF(E24>0,(AJ24/F24),"") | BM24: =+IF(E24>0,(AJ24/G24),"") | BN24: =+IF(E24>0,(AJ24/J24),"") | BP24: =IF(AJ24>0,(N24/AJ24),"") | BQ24: 0 | BR24: =IF(AJ24>0,(AK24/AJ24),"") | BS24: =IF(AJ24>0,(AK24/AJ24),"") | BT24: =IF(J24>0,AD24/J24,"") | BV24: =IF(AN24>0,(E24/AN24),"") | BW24: =IF(AN24>0,(G24/AN24),"") | BX24: =IF(AN24>0,(J24/AN24),"") | BY24: =IF(AN24>0,(K24/AN24),"") | BZ24: =IF(AN24>0,(AJ24/AN24),"") | CA24: =IF(AN24>0,(AK24/AN24),"") | CC24: =IFERROR(((AN24-AO24)*3600)/J24,"-") -> - | CD24: =IFERROR((AR24*3600)/J24,"-") -> - | CE24: =IFERROR((AQ24*3600)/J24,"-") -> - | CF24: =IFERROR((AO24*3600)/J24,"-") -> - | CG24: =IFERROR((AP24*3600)/J24,"-") -> -
A25: =+A24+1 -> 46317 | B25: =+TEXT(A25,"DDD") -> Thu | AX25: =IFERROR(AN25/AW25,"-") -> - | AZ25: =IF(E25>0,F25/E25,"") | BA25: =+IF(E25>0,G25/E25,"") | BB25: =+IF(E25>0,AJ25/E25,"") | BD25: =+IF(G25>0,I25/G25,"") | BE25: =+IF(G25>0,J25/G25,"") | BF25: =+IF(I25>0,L25/I25,"") | BG25: =+IF(SUM(AO25:AR25)>0,AO25/AN25,"") | BH25: =+IF(G25>0,K25/G25,"") | BI25: =+IF(SUM(AO25:AR25)>0,AQ25/AN25,"") | BK25: =+IF(E25>0,(AJ25/E25),"") | BL25: =+IF(E25>0,(AJ25/F25),"") | BM25: =+IF(E25>0,(AJ25/G25),"") | BN25: =+IF(E25>0,(AJ25/J25),"") | BP25: =IF(AJ25>0,(N25/AJ25),"") | BQ25: 0 | BR25: =IF(AJ25>0,(AK25/AJ25),"") | BS25: =IF(AJ25>0,(AK25/AJ25),"") | BT25: =IF(J25>0,AD25/J25,"") | BV25: =IF(AN25>0,(E25/AN25),"") | BW25: =IF(AN25>0,(G25/AN25),"") | BX25: =IF(AN25>0,(J25/AN25),"") | BY25: =IF(AN25>0,(K25/AN25),"") | BZ25: =IF(AN25>0,(AJ25/AN25),"") | CA25: =IF(AN25>0,(AK25/AN25),"") | CC25: =IFERROR(((AN25-AO25)*3600)/J25,"-") -> - | CD25: =IFERROR((AR25*3600)/J25,"-") -> - | CE25: =IFERROR((AQ25*3600)/J25,"-") -> - | CF25: =IFERROR((AO25*3600)/J25,"-") -> - | CG25: =IFERROR((AP25*3600)/J25,"-") -> -
A26: =+A25+1 -> 46318 | B26: =+TEXT(A26,"DDD") -> Fri | AX26: =IFERROR(AN26/AW26,"-") -> - | AZ26: =IF(E26>0,F26/E26,"") | BA26: =+IF(E26>0,G26/E26,"") | BB26: =+IF(E26>0,AJ26/E26,"") | BD26: =+IF(G26>0,I26/G26,"") | BE26: =+IF(G26>0,J26/G26,"") | BF26: =+IF(I26>0,L26/I26,"") | BG26: =+IF(SUM(AO26:AR26)>0,AO26/AN26,"") | BH26: =+IF(G26>0,K26/G26,"") | BI26: =+IF(SUM(AO26:AR26)>0,AQ26/AN26,"") | BK26: =+IF(E26>0,(AJ26/E26),"") | BL26: =+IF(E26>0,(AJ26/F26),"") | BM26: =+IF(E26>0,(AJ26/G26),"") | BN26: =+IF(E26>0,(AJ26/J26),"") | BP26: =IF(AJ26>0,(N26/AJ26),"") | BQ26: 0 | BR26: =IF(AJ26>0,(AK26/AJ26),"") | BS26: =IF(AJ26>0,(AK26/AJ26),"") | BT26: =IF(J26>0,AD26/J26,"") | BV26: =IF(AN26>0,(E26/AN26),"") | BW26: =IF(AN26>0,(G26/AN26),"") | BX26: =IF(AN26>0,(J26/AN26),"") | BY26: =IF(AN26>0,(K26/AN26),"") | BZ26: =IF(AN26>0,(AJ26/AN26),"") | CA26: =IF(AN26>0,(AK26/AN26),"") | CC26: =IFERROR(((AN26-AO26)*3600)/J26,"-") -> - | CD26: =IFERROR((AR26*3600)/J26,"-") -> - | CE26: =IFERROR((AQ26*3600)/J26,"-") -> - | CF26: =IFERROR((AO26*3600)/J26,"-") -> - | CG26: =IFERROR((AP26*3600)/J26,"-") -> -
A27: =+A26+1 -> 46319 | B27: =+TEXT(A27,"DDD") -> Sat | AX27: =IFERROR(AN27/AW27,"-") -> - | AZ27: =IF(E27>0,F27/E27,"") | BA27: =+IF(E27>0,G27/E27,"") | BB27: =+IF(E27>0,AJ27/E27,"") | BD27: =+IF(G27>0,I27/G27,"") | BE27: =+IF(G27>0,J27/G27,"") | BF27: =+IF(I27>0,L27/I27,"") | BG27: =+IF(SUM(AO27:AR27)>0,AO27/AN27,"") | BH27: =+IF(G27>0,K27/G27,"") | BI27: =+IF(SUM(AO27:AR27)>0,AQ27/AN27,"") | BK27: =+IF(E27>0,(AJ27/E27),"") | BL27: =+IF(E27>0,(AJ27/F27),"") | BM27: =+IF(E27>0,(AJ27/G27),"") | BN27: =+IF(E27>0,(AJ27/J27),"") | BP27: =IF(AJ27>0,(N27/AJ27),"") | BQ27: 0 | BR27: =IF(AJ27>0,(AK27/AJ27),"") | BS27: =IF(AJ27>0,(AK27/AJ27),"") | BT27: =IF(J27>0,AD27/J27,"") | BV27: =IF(AN27>0,(E27/AN27),"") | BW27: =IF(AN27>0,(G27/AN27),"") | BX27: =IF(AN27>0,(J27/AN27),"") | BY27: =IF(AN27>0,(K27/AN27),"") | BZ27: =IF(AN27>0,(AJ27/AN27),"") | CA27: =IF(AN27>0,(AK27/AN27),"") | CC27: =IFERROR(((AN27-AO27)*3600)/J27,"-") -> - | CD27: =IFERROR((AR27*3600)/J27,"-") -> - | CE27: =IFERROR((AQ27*3600)/J27,"-") -> - | CF27: =IFERROR((AO27*3600)/J27,"-") -> - | CG27: =IFERROR((AP27*3600)/J27,"-") -> -
A28: =+A27+1 -> 46320 | B28: =+TEXT(A28,"DDD") -> Sun | AX28: =IFERROR(AN28/AW28,"-") -> - | AZ28: =IF(E28>0,F28/E28,"") | BA28: =+IF(E28>0,G28/E28,"") | BB28: =+IF(E28>0,AJ28/E28,"") | BD28: =+IF(G28>0,I28/G28,"") | BE28: =+IF(G28>0,J28/G28,"") | BF28: =+IF(I28>0,L28/I28,"") | BG28: =+IF(SUM(AO28:AR28)>0,AO28/AN28,"") | BH28: =+IF(G28>0,K28/G28,"") | BI28: =+IF(SUM(AO28:AR28)>0,AQ28/AN28,"") | BK28: =+IF(E28>0,(AJ28/E28),"") | BL28: =+IF(E28>0,(AJ28/F28),"") | BM28: =+IF(E28>0,(AJ28/G28),"") | BN28: =+IF(E28>0,(AJ28/J28),"") | BP28: =IF(AJ28>0,(N28/AJ28),"") | BQ28: 0 | BR28: =IF(AJ28>0,(AK28/AJ28),"") | BS28: =IF(AJ28>0,(AK28/AJ28),"") | BT28: =IF(J28>0,AD28/J28,"") | BV28: =IF(AN28>0,(E28/AN28),"") | BW28: =IF(AN28>0,(G28/AN28),"") | BX28: =IF(AN28>0,(J28/AN28),"") | BY28: =IF(AN28>0,(K28/AN28),"") | BZ28: =IF(AN28>0,(AJ28/AN28),"") | CA28: =IF(AN28>0,(AK28/AN28),"") | CC28: =IFERROR(((AN28-AO28)*3600)/J28,"-") -> - | CD28: =IFERROR((AR28*3600)/J28,"-") -> - | CE28: =IFERROR((AQ28*3600)/J28,"-") -> - | CF28: =IFERROR((AO28*3600)/J28,"-") -> - | CG28: =IFERROR((AP28*3600)/J28,"-") -> -
A29: =+A28+1 -> 46321 | B29: =+TEXT(A29,"DDD") -> Mon | AX29: =IFERROR(AN29/AW29,"-") -> - | AZ29: =IF(E29>0,F29/E29,"") | BA29: =+IF(E29>0,G29/E29,"") | BB29: =+IF(E29>0,AJ29/E29,"") | BD29: =+IF(G29>0,I29/G29,"") | BE29: =+IF(G29>0,J29/G29,"") | BF29: =+IF(I29>0,L29/I29,"") | BG29: =+IF(SUM(AO29:AR29)>0,AO29/AN29,"") | BH29: =+IF(G29>0,K29/G29,"") | BI29: =+IF(SUM(AO29:AR29)>0,AQ29/AN29,"") | BK29: =+IF(E29>0,(AJ29/E29),"") | BL29: =+IF(E29>0,(AJ29/F29),"") | BM29: =+IF(E29>0,(AJ29/G29),"") | BN29: =+IF(E29>0,(AJ29/J29),"") | BP29: =IF(AJ29>0,(N29/AJ29),"") | BQ29: 0 | BR29: =IF(AJ29>0,(AK29/AJ29),"") | BS29: =IF(AJ29>0,(AK29/AJ29),"") | BT29: =IF(J29>0,AD29/J29,"") | BV29: =IF(AN29>0,(E29/AN29),"") | BW29: =IF(AN29>0,(G29/AN29),"") | BX29: =IF(AN29>0,(J29/AN29),"") | BY29: =IF(AN29>0,(K29/AN29),"") | BZ29: =IF(AN29>0,(AJ29/AN29),"") | CA29: =IF(AN29>0,(AK29/AN29),"") | CC29: =IFERROR(((AN29-AO29)*3600)/J29,"-") -> - | CD29: =IFERROR((AR29*3600)/J29,"-") -> - | CE29: =IFERROR((AQ29*3600)/J29,"-") -> - | CF29: =IFERROR((AO29*3600)/J29,"-") -> - | CG29: =IFERROR((AP29*3600)/J29,"-") -> -
... A34: =+A33+1 -> 46326 | B34: =+TEXT(A34,"DDD") -> Sat | AX34: =IFERROR(AN34/AW34,"-") -> - | AZ34: =IF(E34>0,F34/E34,"") | BA34: =+IF(E34>0,G34/E34,"") | BB34: =+IF(E34>0,AJ34/E34,"") | BD34: =+IF(G34>0,I34/G34,"") | BE34: =+IF(G34>0,J34/G34,"") | BF34: =+IF(I34>0,L34/I34,"") | BG34: =+IF(SUM(AO34:AR34)>0,AO34/AN34,"") | BH34: =+IF(G34>0,K34/G34,"") | BI34: =+IF(SUM(AO34:AR34)>0,AQ34/AN34,"") | BK34: =+IF(E34>0,(AJ34/E34),"") | BL34: =+IF(E34>0,(AJ34/F34),"") | BM34: =+IF(E34>0,(AJ34/G34),"") | BN34: =+IF(E34>0,(AJ34/J34),"") | BP34: =IF(AJ34>0,(N34/AJ34),"") | BQ34: 0 | BR34: =IF(AJ34>0,(AK34/AJ34),"") | BS34: =IF(AJ34>0,(AK34/AJ34),"") | BT34: =IF(J34>0,AD34/J34,"") | BV34: =IF(AN34>0,(E34/AN34),"") | BW34: =IF(AN34>0,(G34/AN34),"") | BX34: =IF(AN34>0,(J34/AN34),"") | BY34: =IF(AN34>0,(K34/AN34),"") | BZ34: =IF(AN34>0,(AJ34/AN34),"") | CA34: =IF(AN34>0,(AK34/AN34),"") | CC34: =IFERROR(((AN34-AO34)*3600)/J34,"-") -> - | CD34: =IFERROR((AR34*3600)/J34,"-") -> - | CE34: =IFERROR((AQ34*3600)/J34,"-") -> - | CF34: =IFERROR((AO34*3600)/J34,"-") -> - | CG34: =IFERROR((AP34*3600)/J34,"-") -> -
A35: Average | C35: =AVERAGE(C4:C34) -> #DIV/0! | D35: =AVERAGE(D4:D34) -> #DIV/0! | E35: =AVERAGE(E4:E34) -> #DIV/0! | F35: =AVERAGE(F4:F34) -> #DIV/0! | G35: =AVERAGE(G4:G34) -> #DIV/0! | H35: =AVERAGE(H4:H34) -> #DIV/0! | I35: =AVERAGE(I4:I34) -> #DIV/0! | J35: =AVERAGE(J4:J34) -> #DIV/0! | ... AW35: =AVERAGE(AW4:AW34) -> #DIV/0! | AX35: =IFERROR(AN35/AW35,"-") -> - | AZ35: =IF(E35>0,F35/E35,"") -> #DIV/0! | BA35: =+IF(E35>0,G35/E35,"") -> #DIV/0! | BB35: =+IF(E35>0,AJ35/E35,"") -> #DIV/0! | BD35: =+IF(G35>0,I35/G35,"") -> #DIV/0! | BE35: =+IF(G35>0,J35/G35,"") -> #DIV/0! | BF35: =+IF(I35>0,L35/I35,"") -> #DIV/0! | BG35: =+IF(SUM(AO35:AR35)>0,AO35/AN35,"") -> #DIV/0! | BH35: =+IF(G35>0,K35/G35,"") -> #DIV/0! | BI35: =+IF(SUM(AO35:AR35)>0,AQ35/AN35,"") -> #DIV/0! | BK35: =+IF(E35>0,(AJ35/E35),"") -> #DIV/0! | BL35: =+IF(E35>0,(AJ35/F35),"") -> #DIV/0! | BM35: =+IF(E35>0,(AJ35/G35),"") -> #DIV/0! | BN35: =+IF(E35>0,(AJ35/J35),"") -> #DIV/0! | BP35: =IF(AJ35>0,(N35/AJ35),"") -> #DIV/0! | BQ35: 0 | BR35: =IF(AJ35>0,(AK35/AJ35),"") -> #DIV/0! | BS35: =IF(AJ35>0,(AK35/AJ35),"") -> #DIV/0! | BT35: =IF(J35>0,AD35/J35,"") -> #DIV/0! | BV35: =IF(AN35>0,(E35/AN35),"") -> #DIV/0! | BW35: =IF(AN35>0,(G35/AN35),"") -> #DIV/0! | BX35: =IF(AN35>0,(J35/AN35),"") -> #DIV/0! | BY35: =IF(AN35>0,(K35/AN35),"") -> #DIV/0! | BZ35: =IF(AN35>0,(AJ35/AN35),"") -> #DIV/0! | CA35: =IF(AN35>0,(AK35/AN35),"") -> #DIV/0! | CC35: =IFERROR(((AN35-AO35)*3600)/J35,"-") -> - | CD35: =IFERROR((AR35*3600)/J35,"-") -> - | CE35: =IFERROR((AQ35*3600)/J35,"-") -> - | CF35: =IFERROR((AO35*3600)/J35,"-") -> - | CG35: =IFERROR((AP35*3600)/J35,"-") -> -
A36: Total | C36: =SUM(C4:C34) -> 0 | D36: =SUM(D4:D34) -> 0 | E36: =SUM(E4:E34) -> 0 | F36: =SUM(F4:F34) -> 0 | G36: =SUM(G4:G34) -> 0 | H36: =SUM(H4:H34) -> 0 | I36: =SUM(I4:I34) -> 0 | J36: =SUM(J4:J34) -> 0 | ... AW36: =SUM(AW4:AW34) -> 0 | AX36: =IFERROR(AN36/AW36,"-") -> - | AZ36: =IF(E36>0,F36/E36,"") | BA36: =+IF(E36>0,G36/E36,"") | BB36: =+IF(E36>0,AJ36/E36,"") | BD36: =+IF(G36>0,I36/G36,"") | BE36: =+IF(G36>0,J36/G36,"") | BF36: =+IF(I36>0,L36/I36,"") | BG36: =+IF(SUM(AO36:AR36)>0,AO36/AN36,"") | BH36: =+IF(G36>0,K36/G36,"") | BI36: =+IF(SUM(AO36:AR36)>0,AQ36/AN36,"") | BK36: =+IF(E36>0,(AJ36/E36),"") | BL36: =+IF(E36>0,(AJ36/F36),"") | BM36: =+IF(E36>0,(AJ36/G36),"") | BN36: =+IF(E36>0,(AJ36/J36),"") | BP36: =IF(AJ36>0,(N36/AJ36),"") | BQ36: 0 | BR36: =IF(AJ36>0,(AK36/AJ36),"") | BS36: =IF(AJ36>0,(AK36/AJ36),"") | BT36: =IF(J36>0,AD36/J36,"") | BV36: =IF(AN36>0,(E36/AN36),"") | BW36: =IF(AN36>0,(G36/AN36),"") | BX36: =IF(AN36>0,(J36/AN36),"") | BY36: =IF(AN36>0,(K36/AN36),"") | BZ36: =IF(AN36>0,(AJ36/AN36),"") | CA36: =IF(AN36>0,(AK36/AN36),"") | CC36: =IFERROR(((AN36-AO36)*3600)/J36,"-") -> - | CD36: =IFERROR((AR36*3600)/J36,"-") -> - | CE36: =IFERROR((AQ36*3600)/J36,"-") -> - | CF36: =IFERROR((AO36*3600)/J36,"-") -> - | CG36: =IFERROR((AP36*3600)/J36,"-") -> -

Sheet EL_DEL_CD2_PTP_
A1: DIALER MIS | AZ1: Dashboard Measurements | BD1: System Efficiency | BK1: Contact Rates | BP1: Contact Termcodes | BV1: Agent Hour Statistics | CC1: Average Call time Statistics
A2: Date | B2: Day | C2: Total Accounts | D2: Accounts Excluded | E2: Accounts Scheduled | F2: Accounts Called | G2: Dials | H2: Actual Dialer Dials | I2: Answers | J2: Connects | K2: Make Calls | L2: Aborts | M2: DROP | N2: PTP | O2: PAD | P2: OTP | Q2: DISP | R2: WN | S2: NC | T2: AU | U2: VOML | V2: CT | W2: TC | X2: EWS | Y2: WS | Z2: DS | AA2: BCTP | AB2: DPTP | AC2: WH | AD2: LB | AE2: TCBL | AF2: TPC | AG2: RTP | AH2: CBL | AI2: TOTAL CALLS | AJ2: TOTAL Contacts | AK2: TOTAL Promises | AL2: Logged in Time | AM2: Not Ready Time | AN2: Time On System | AO2: Idle Time | AP2: Preview Time | AQ2: Wrap Time | AR2: Talk Time | AS2: Agent Hours | AT2: Cur_Bal | AU2: PTP Value | AV2: Total PTP Value | AW2: Count Of Agents | AX2: Average TOS | AZ2: Completion Rate | BA2: Penetration | BB2: Contact Rate | BD2: Answer Rate | BE2: Connect Rate | BF2: Abort / Answer Rate | BG2: Idle Rate | BH2: Make Call Rate | BI2: Wrap Rate | BK2: Contact / Download | BL2: Contact / Accounts called | BM2: Contact / Dial | BN2: Contact / Connect | BP2: PTP Rate | BQ2: Pick-Up Rate | BR2: PTP+PAD rate | BS2: CallBack Rate | BT2: LB Rate | BV2: Accounts per Hour | BW2: Dials per Hour | BX2: Connects per Hour | BY2: Make Call per Hour | BZ2: Contacts per Hour | CA2: Promises per Hour | CC2: AHT | CD2: Talk | CE2: Wrap | CF2: Idle | CG2: Preview
AX3: Count Of Agents
A4: =EL_DEL_CD2_JO_!A4 -> 46296 | B4: =+TEXT(A4,"DDD") -> Thu | AX4: =IFERROR(AN4/AW4,"-") -> - | AZ4: =IF(E4>0,F4/E4,"") | BA4: =+IF(E4>0,G4/E4,"") | BB4: =+IF(E4>0,AJ4/E4,"") | BD4: =+IF(G4>0,I4/G4,"") | BE4: =+IF(G4>0,J4/G4,"") | BF4: =+IF(I4>0,L4/I4,"") | BG4: =+IF(SUM(AO4:AR4)>0,AO4/AN4,"") | BH4: =+IF(G4>0,K4/G4,"") | BI4: =+IF(SUM(AO4:AR4)>0,AQ4/AN4,"") | BK4: =+IF(E4>0,(AJ4/E4),"") | BL4: =+IF(E4>0,(AJ4/F4),"") | BM4: =+IF(E4>0,(AJ4/G4),"") | BN4: =+IF(E4>0,(AJ4/J4),"") | BP4: =IF(AJ4>0,(N4/AJ4),"") | BQ4: 0 | BR4: =IF(AJ4>0,(AK4/AJ4),"") | BS4: =IF(AJ4>0,(AK4/AJ4),"") | BT4: =IF(J4>0,AD4/J4,"") | BV4: =IF(AN4>0,(E4/AN4),"") | BW4: =IF(AN4>0,(G4/AN4),"") | BX4: =IF(AN4>0,(J4/AN4),"") | BY4: =IF(AN4>0,(K4/AN4),"") | BZ4: =IF(AN4>0,(AJ4/AN4),"") | CA4: =IF(AN4>0,(AK4/AN4),"") | CC4: =IFERROR(((AN4-AO4)*3600)/J4,"-") -> - | CD4: =IFERROR((AR4*3600)/J4,"-") -> - | CE4: =IFERROR((AQ4*3600)/J4,"-") -> - | CF4: =IFERROR((AO4*3600)/J4,"-") -> - | CG4: =IFERROR((AP4*3600)/J4,"-") -> -
A5: =EL_DEL_CD2_JO_!A5 -> 46297 | B5: =+TEXT(A5,"DDD") -> Fri | AX5: =IFERROR(AN5/AW5,"-") -> - | AZ5: =IF(E5>0,F5/E5,"") | BA5: =+IF(E5>0,G5/E5,"") | BB5: =+IF(E5>0,AJ5/E5,"") | BD5: =+IF(G5>0,I5/G5,"") | BE5: =+IF(G5>0,J5/G5,"") | BF5: =+IF(I5>0,L5/I5,"") | BG5: =+IF(SUM(AO5:AR5)>0,AO5/AN5,"") | BH5: =+IF(G5>0,K5/G5,"") | BI5: =+IF(SUM(AO5:AR5)>0,AQ5/AN5,"") | BK5: =+IF(E5>0,(AJ5/E5),"") | BL5: =+IF(E5>0,(AJ5/F5),"") | BM5: =+IF(E5>0,(AJ5/G5),"") | BN5: =+IF(E5>0,(AJ5/J5),"") | BP5: =IF(AJ5>0,(N5/AJ5),"") | BQ5: 0 | BR5: =IF(AJ5>0,(AK5/AJ5),"") | BS5: =IF(AJ5>0,(AK5/AJ5),"") | BT5: =IF(J5>0,AD5/J5,"") | BV5: =IF(AN5>0,(E5/AN5),"") | BW5: =IF(AN5>0,(G5/AN5),"") | BX5: =IF(AN5>0,(J5/AN5),"") | BY5: =IF(AN5>0,(K5/AN5),"") | BZ5: =IF(AN5>0,(AJ5/AN5),"") | CA5: =IF(AN5>0,(AK5/AN5),"") | CC5: =IFERROR(((AN5-AO5)*3600)/J5,"-") -> - | CD5: =IFERROR((AR5*3600)/J5,"-") -> - | CE5: =IFERROR((AQ5*3600)/J5,"-") -> - | CF5: =IFERROR((AO5*3600)/J5,"-") -> - | CG5: =IFERROR((AP5*3600)/J5,"-") -> -
A6: =EL_DEL_CD2_JO_!A6 -> 46298 | B6: =+TEXT(A6,"DDD") -> Sat | AX6: =IFERROR(AN6/AW6,"-") -> - | AZ6: =IF(E6>0,F6/E6,"") | BA6: =+IF(E6>0,G6/E6,"") | BB6: =+IF(E6>0,AJ6/E6,"") | BD6: =+IF(G6>0,I6/G6,"") | BE6: =+IF(G6>0,J6/G6,"") | BF6: =+IF(I6>0,L6/I6,"") | BG6: =+IF(SUM(AO6:AR6)>0,AO6/AN6,"") | BH6: =+IF(G6>0,K6/G6,"") | BI6: =+IF(SUM(AO6:AR6)>0,AQ6/AN6,"") | BK6: =+IF(E6>0,(AJ6/E6),"") | BL6: =+IF(E6>0,(AJ6/F6),"") | BM6: =+IF(E6>0,(AJ6/G6),"") | BN6: =+IF(E6>0,(AJ6/J6),"") | BP6: =IF(AJ6>0,(N6/AJ6),"") | BQ6: 0 | BR6: =IF(AJ6>0,(AK6/AJ6),"") | BS6: =IF(AJ6>0,(AK6/AJ6),"") | BT6: =IF(J6>0,AD6/J6,"") | BV6: =IF(AN6>0,(E6/AN6),"") | BW6: =IF(AN6>0,(G6/AN6),"") | BX6: =IF(AN6>0,(J6/AN6),"") | BY6: =IF(AN6>0,(K6/AN6),"") | BZ6: =IF(AN6>0,(AJ6/AN6),"") | CA6: =IF(AN6>0,(AK6/AN6),"") | CC6: =IFERROR(((AN6-AO6)*3600)/J6,"-") -> - | CD6: =IFERROR((AR6*3600)/J6,"-") -> - | CE6: =IFERROR((AQ6*3600)/J6,"-") -> - | CF6: =IFERROR((AO6*3600)/J6,"-") -> - | CG6: =IFERROR((AP6*3600)/J6,"-") -> -
A7: =EL_DEL_CD2_JO_!A7 -> 46299 | B7: =+TEXT(A7,"DDD") -> Sun | AX7: =IFERROR(AN7/AW7,"-") -> - | AZ7: =IF(E7>0,F7/E7,"") | BA7: =+IF(E7>0,G7/E7,"") | BB7: =+IF(E7>0,AJ7/E7,"") | BD7: =+IF(G7>0,I7/G7,"") | BE7: =+IF(G7>0,J7/G7,"") | BF7: =+IF(I7>0,L7/I7,"") | BG7: =+IF(SUM(AO7:AR7)>0,AO7/AN7,"") | BH7: =+IF(G7>0,K7/G7,"") | BI7: =+IF(SUM(AO7:AR7)>0,AQ7/AN7,"") | BK7: =+IF(E7>0,(AJ7/E7),"") | BL7: =+IF(E7>0,(AJ7/F7),"") | BM7: =+IF(E7>0,(AJ7/G7),"") | BN7: =+IF(E7>0,(AJ7/J7),"") | BP7: =IF(AJ7>0,(N7/AJ7),"") | BQ7: 0 | BR7: =IF(AJ7>0,(AK7/AJ7),"") | BS7: =IF(AJ7>0,(AK7/AJ7),"") | BT7: =IF(J7>0,AD7/J7,"") | BV7: =IF(AN7>0,(E7/AN7),"") | BW7: =IF(AN7>0,(G7/AN7),"") | BX7: =IF(AN7>0,(J7/AN7),"") | BY7: =IF(AN7>0,(K7/AN7),"") | BZ7: =IF(AN7>0,(AJ7/AN7),"") | CA7: =IF(AN7>0,(AK7/AN7),"") | CC7: =IFERROR(((AN7-AO7)*3600)/J7,"-") -> - | CD7: =IFERROR((AR7*3600)/J7,"-") -> - | CE7: =IFERROR((AQ7*3600)/J7,"-") -> - | CF7: =IFERROR((AO7*3600)/J7,"-") -> - | CG7: =IFERROR((AP7*3600)/J7,"-") -> -
A8: =EL_DEL_CD2_JO_!A8 -> 46300 | B8: =+TEXT(A8,"DDD") -> Mon | AX8: =IFERROR(AN8/AW8,"-") -> - | AZ8: =IF(E8>0,F8/E8,"") | BA8: =+IF(E8>0,G8/E8,"") | BB8: =+IF(E8>0,AJ8/E8,"") | BD8: =+IF(G8>0,I8/G8,"") | BE8: =+IF(G8>0,J8/G8,"") | BF8: =+IF(I8>0,L8/I8,"") | BG8: =+IF(SUM(AO8:AR8)>0,AO8/AN8,"") | BH8: =+IF(G8>0,K8/G8,"") | BI8: =+IF(SUM(AO8:AR8)>0,AQ8/AN8,"") | BK8: =+IF(E8>0,(AJ8/E8),"") | BL8: =+IF(E8>0,(AJ8/F8),"") | BM8: =+IF(E8>0,(AJ8/G8),"") | BN8: =+IF(E8>0,(AJ8/J8),"") | BP8: =IF(AJ8>0,(N8/AJ8),"") | BQ8: 0 | BR8: =IF(AJ8>0,(AK8/AJ8),"") | BS8: =IF(AJ8>0,(AK8/AJ8),"") | BT8: =IF(J8>0,AD8/J8,"") | BV8: =IF(AN8>0,(E8/AN8),"") | BW8: =IF(AN8>0,(G8/AN8),"") | BX8: =IF(AN8>0,(J8/AN8),"") | BY8: =IF(AN8>0,(K8/AN8),"") | BZ8: =IF(AN8>0,(AJ8/AN8),"") | CA8: =IF(AN8>0,(AK8/AN8),"") | CC8: =IFERROR(((AN8-AO8)*3600)/J8,"-") -> - | CD8: =IFERROR((AR8*3600)/J8,"-") -> - | CE8: =IFERROR((AQ8*3600)/J8,"-") -> - | CF8: =IFERROR((AO8*3600)/J8,"-") -> - | CG8: =IFERROR((AP8*3600)/J8,"-") -> -
A9: =EL_DEL_CD2_JO_!A9 -> 46301 | B9: =+TEXT(A9,"DDD") -> Tue | AX9: =IFERROR(AN9/AW9,"-") -> - | AZ9: =IF(E9>0,F9/E9,"") | BA9: =+IF(E9>0,G9/E9,"") | BB9: =+IF(E9>0,AJ9/E9,"") | BD9: =+IF(G9>0,I9/G9,"") | BE9: =+IF(G9>0,J9/G9,"") | BF9: =+IF(I9>0,L9/I9,"") | BG9: =+IF(SUM(AO9:AR9)>0,AO9/AN9,"") | BH9: =+IF(G9>0,K9/G9,"") | BI9: =+IF(SUM(AO9:AR9)>0,AQ9/AN9,"") | BK9: =+IF(E9>0,(AJ9/E9),"") | BL9: =+IF(E9>0,(AJ9/F9),"") | BM9: =+IF(E9>0,(AJ9/G9),"") | BN9: =+IF(E9>0,(AJ9/J9),"") | BP9: =IF(AJ9>0,(N9/AJ9),"") | BQ9: 0 | BR9: =IF(AJ9>0,(AK9/AJ9),"") | BS9: =IF(AJ9>0,(AK9/AJ9),"") | BT9: =IF(J9>0,AD9/J9,"") | BV9: =IF(AN9>0,(E9/AN9),"") | BW9: =IF(AN9>0,(G9/AN9),"") | BX9: =IF(AN9>0,(J9/AN9),"") | BY9: =IF(AN9>0,(K9/AN9),"") | BZ9: =IF(AN9>0,(AJ9/AN9),"") | CA9: =IF(AN9>0,(AK9/AN9),"") | CC9: =IFERROR(((AN9-AO9)*3600)/J9,"-") -> - | CD9: =IFERROR((AR9*3600)/J9,"-") -> - | CE9: =IFERROR((AQ9*3600)/J9,"-") -> - | CF9: =IFERROR((AO9*3600)/J9,"-") -> - | CG9: =IFERROR((AP9*3600)/J9,"-") -> -
A10: =EL_DEL_CD2_JO_!A10 -> 46302 | B10: =+TEXT(A10,"DDD") -> Wed | AX10: =IFERROR(AN10/AW10,"-") -> - | AZ10: =IF(E10>0,F10/E10,"") | BA10: =+IF(E10>0,G10/E10,"") | BB10: =+IF(E10>0,AJ10/E10,"") | BD10: =+IF(G10>0,I10/G10,"") | BE10: =+IF(G10>0,J10/G10,"") | BF10: =+IF(I10>0,L10/I10,"") | BG10: =+IF(SUM(AO10:AR10)>0,AO10/AN10,"") | BH10: =+IF(G10>0,K10/G10,"") | BI10: =+IF(SUM(AO10:AR10)>0,AQ10/AN10,"") | BK10: =+IF(E10>0,(AJ10/E10),"") | BL10: =+IF(E10>0,(AJ10/F10),"") | BM10: =+IF(E10>0,(AJ10/G10),"") | BN10: =+IF(E10>0,(AJ10/J10),"") | BP10: =IF(AJ10>0,(N10/AJ10),"") | BQ10: 0 | BR10: =IF(AJ10>0,(AK10/AJ10),"") | BS10: =IF(AJ10>0,(AK10/AJ10),"") | BT10: =IF(J10>0,AD10/J10,"") | BV10: =IF(AN10>0,(E10/AN10),"") | BW10: =IF(AN10>0,(G10/AN10),"") | BX10: =IF(AN10>0,(J10/AN10),"") | BY10: =IF(AN10>0,(K10/AN10),"") | BZ10: =IF(AN10>0,(AJ10/AN10),"") | CA10: =IF(AN10>0,(AK10/AN10),"") | CC10: =IFERROR(((AN10-AO10)*3600)/J10,"-") -> - | CD10: =IFERROR((AR10*3600)/J10,"-") -> - | CE10: =IFERROR((AQ10*3600)/J10,"-") -> - | CF10: =IFERROR((AO10*3600)/J10,"-") -> - | CG10: =IFERROR((AP10*3600)/J10,"-") -> -
A11: =EL_DEL_CD2_JO_!A11 -> 46303 | B11: =+TEXT(A11,"DDD") -> Thu | AX11: =IFERROR(AN11/AW11,"-") -> - | AZ11: =IF(E11>0,F11/E11,"") | BA11: =+IF(E11>0,G11/E11,"") | BB11: =+IF(E11>0,AJ11/E11,"") | BD11: =+IF(G11>0,I11/G11,"") | BE11: =+IF(G11>0,J11/G11,"") | BF11: =+IF(I11>0,L11/I11,"") | BG11: =+IF(SUM(AO11:AR11)>0,AO11/AN11,"") | BH11: =+IF(G11>0,K11/G11,"") | BI11: =+IF(SUM(AO11:AR11)>0,AQ11/AN11,"") | BK11: =+IF(E11>0,(AJ11/E11),"") | BL11: =+IF(E11>0,(AJ11/F11),"") | BM11: =+IF(E11>0,(AJ11/G11),"") | BN11: =+IF(E11>0,(AJ11/J11),"") | BP11: =IF(AJ11>0,(N11/AJ11),"") | BQ11: 0 | BR11: =IF(AJ11>0,(AK11/AJ11),"") | BS11: =IF(AJ11>0,(AK11/AJ11),"") | BT11: =IF(J11>0,AD11/J11,"") | BV11: =IF(AN11>0,(E11/AN11),"") | BW11: =IF(AN11>0,(G11/AN11),"") | BX11: =IF(AN11>0,(J11/AN11),"") | BY11: =IF(AN11>0,(K11/AN11),"") | BZ11: =IF(AN11>0,(AJ11/AN11),"") | CA11: =IF(AN11>0,(AK11/AN11),"") | CC11: =IFERROR(((AN11-AO11)*3600)/J11,"-") -> - | CD11: =IFERROR((AR11*3600)/J11,"-") -> - | CE11: =IFERROR((AQ11*3600)/J11,"-") -> - | CF11: =IFERROR((AO11*3600)/J11,"-") -> - | CG11: =IFERROR((AP11*3600)/J11,"-") -> -
A12: =EL_DEL_CD2_JO_!A12 -> 46304 | B12: =+TEXT(A12,"DDD") -> Fri | AX12: =IFERROR(AN12/AW12,"-") -> - | AZ12: =IF(E12>0,F12/E12,"") | BA12: =+IF(E12>0,G12/E12,"") | BB12: =+IF(E12>0,AJ12/E12,"") | BD12: =+IF(G12>0,I12/G12,"") | BE12: =+IF(G12>0,J12/G12,"") | BF12: =+IF(I12>0,L12/I12,"") | BG12: =+IF(SUM(AO12:AR12)>0,AO12/AN12,"") | BH12: =+IF(G12>0,K12/G12,"") | BI12: =+IF(SUM(AO12:AR12)>0,AQ12/AN12,"") | BK12: =+IF(E12>0,(AJ12/E12),"") | BL12: =+IF(E12>0,(AJ12/F12),"") | BM12: =+IF(E12>0,(AJ12/G12),"") | BN12: =+IF(E12>0,(AJ12/J12),"") | BP12: =IF(AJ12>0,(N12/AJ12),"") | BQ12: 0 | BR12: =IF(AJ12>0,(AK12/AJ12),"") | BS12: =IF(AJ12>0,(AK12/AJ12),"") | BT12: =IF(J12>0,AD12/J12,"") | BV12: =IF(AN12>0,(E12/AN12),"") | BW12: =IF(AN12>0,(G12/AN12),"") | BX12: =IF(AN12>0,(J12/AN12),"") | BY12: =IF(AN12>0,(K12/AN12),"") | BZ12: =IF(AN12>0,(AJ12/AN12),"") | CA12: =IF(AN12>0,(AK12/AN12),"") | CC12: =IFERROR(((AN12-AO12)*3600)/J12,"-") -> - | CD12: =IFERROR((AR12*3600)/J12,"-") -> - | CE12: =IFERROR((AQ12*3600)/J12,"-") -> - | CF12: =IFERROR((AO12*3600)/J12,"-") -> - | CG12: =IFERROR((AP12*3600)/J12,"-") -> -
A13: =EL_DEL_CD2_JO_!A13 -> 46305 | B13: =+TEXT(A13,"DDD") -> Sat | AX13: =IFERROR(AN13/AW13,"-") -> - | AZ13: =IF(E13>0,F13/E13,"") | BA13: =+IF(E13>0,G13/E13,"") | BB13: =+IF(E13>0,AJ13/E13,"") | BD13: =+IF(G13>0,I13/G13,"") | BE13: =+IF(G13>0,J13/G13,"") | BF13: =+IF(I13>0,L13/I13,"") | BG13: =+IF(SUM(AO13:AR13)>0,AO13/AN13,"") | BH13: =+IF(G13>0,K13/G13,"") | BI13: =+IF(SUM(AO13:AR13)>0,AQ13/AN13,"") | BK13: =+IF(E13>0,(AJ13/E13),"") | BL13: =+IF(E13>0,(AJ13/F13),"") | BM13: =+IF(E13>0,(AJ13/G13),"") | BN13: =+IF(E13>0,(AJ13/J13),"") | BP13: =IF(AJ13>0,(N13/AJ13),"") | BQ13: 0 | BR13: =IF(AJ13>0,(AK13/AJ13),"") | BS13: =IF(AJ13>0,(AK13/AJ13),"") | BT13: =IF(J13>0,AD13/J13,"") | BV13: =IF(AN13>0,(E13/AN13),"") | BW13: =IF(AN13>0,(G13/AN13),"") | BX13: =IF(AN13>0,(J13/AN13),"") | BY13: =IF(AN13>0,(K13/AN13),"") | BZ13: =IF(AN13>0,(AJ13/AN13),"") | CA13: =IF(AN13>0,(AK13/AN13),"") | CC13: =IFERROR(((AN13-AO13)*3600)/J13,"-") -> - | CD13: =IFERROR((AR13*3600)/J13,"-") -> - | CE13: =IFERROR((AQ13*3600)/J13,"-") -> - | CF13: =IFERROR((AO13*3600)/J13,"-") -> - | CG13: =IFERROR((AP13*3600)/J13,"-") -> -
A14: =EL_DEL_CD2_JO_!A14 -> 46306 | B14: =+TEXT(A14,"DDD") -> Sun | AX14: =IFERROR(AN14/AW14,"-") -> - | AZ14: =IF(E14>0,F14/E14,"") | BA14: =+IF(E14>0,G14/E14,"") | BB14: =+IF(E14>0,AJ14/E14,"") | BD14: =+IF(G14>0,I14/G14,"") | BE14: =+IF(G14>0,J14/G14,"") | BF14: =+IF(I14>0,L14/I14,"") | BG14: =+IF(SUM(AO14:AR14)>0,AO14/AN14,"") | BH14: =+IF(G14>0,K14/G14,"") | BI14: =+IF(SUM(AO14:AR14)>0,AQ14/AN14,"") | BK14: =+IF(E14>0,(AJ14/E14),"") | BL14: =+IF(E14>0,(AJ14/F14),"") | BM14: =+IF(E14>0,(AJ14/G14),"") | BN14: =+IF(E14>0,(AJ14/J14),"") | BP14: =IF(AJ14>0,(N14/AJ14),"") | BQ14: 0 | BR14: =IF(AJ14>0,(AK14/AJ14),"") | BS14: =IF(AJ14>0,(AK14/AJ14),"") | BT14: =IF(J14>0,AD14/J14,"") | BV14: =IF(AN14>0,(E14/AN14),"") | BW14: =IF(AN14>0,(G14/AN14),"") | BX14: =IF(AN14>0,(J14/AN14),"") | BY14: =IF(AN14>0,(K14/AN14),"") | BZ14: =IF(AN14>0,(AJ14/AN14),"") | CA14: =IF(AN14>0,(AK14/AN14),"") | CC14: =IFERROR(((AN14-AO14)*3600)/J14,"-") -> - | CD14: =IFERROR((AR14*3600)/J14,"-") -> - | CE14: =IFERROR((AQ14*3600)/J14,"-") -> - | CF14: =IFERROR((AO14*3600)/J14,"-") -> - | CG14: =IFERROR((AP14*3600)/J14,"-") -> -
A15: =EL_DEL_CD2_JO_!A15 -> 46307 | B15: =+TEXT(A15,"DDD") -> Mon | AX15: =IFERROR(AN15/AW15,"-") -> - | AZ15: =IF(E15>0,F15/E15,"") | BA15: =+IF(E15>0,G15/E15,"") | BB15: =+IF(E15>0,AJ15/E15,"") | BD15: =+IF(G15>0,I15/G15,"") | BE15: =+IF(G15>0,J15/G15,"") | BF15: =+IF(I15>0,L15/I15,"") | BG15: =+IF(SUM(AO15:AR15)>0,AO15/AN15,"") | BH15: =+IF(G15>0,K15/G15,"") | BI15: =+IF(SUM(AO15:AR15)>0,AQ15/AN15,"") | BK15: =+IF(E15>0,(AJ15/E15),"") | BL15: =+IF(E15>0,(AJ15/F15),"") | BM15: =+IF(E15>0,(AJ15/G15),"") | BN15: =+IF(E15>0,(AJ15/J15),"") | BP15: =IF(AJ15>0,(N15/AJ15),"") | BQ15: 0 | BR15: =IF(AJ15>0,(AK15/AJ15),"") | BS15: =IF(AJ15>0,(AK15/AJ15),"") | BT15: =IF(J15>0,AD15/J15,"") | BV15: =IF(AN15>0,(E15/AN15),"") | BW15: =IF(AN15>0,(G15/AN15),"") | BX15: =IF(AN15>0,(J15/AN15),"") | BY15: =IF(AN15>0,(K15/AN15),"") | BZ15: =IF(AN15>0,(AJ15/AN15),"") | CA15: =IF(AN15>0,(AK15/AN15),"") | CC15: =IFERROR(((AN15-AO15)*3600)/J15,"-") -> - | CD15: =IFERROR((AR15*3600)/J15,"-") -> - | CE15: =IFERROR((AQ15*3600)/J15,"-") -> - | CF15: =IFERROR((AO15*3600)/J15,"-") -> - | CG15: =IFERROR((AP15*3600)/J15,"-") -> -
... A34: =EL_DEL_CD2_JO_!A34 -> 46326 | B34: =+TEXT(A34,"DDD") -> Sat | AX34: =IFERROR(AN34/AW34,"-") -> - | AZ34: =IF(E34>0,F34/E34,"") | BA34: =+IF(E34>0,G34/E34,"") | BB34: =+IF(E34>0,AJ34/E34,"") | BD34: =+IF(G34>0,I34/G34,"") | BE34: =+IF(G34>0,J34/G34,"") | BF34: =+IF(I34>0,L34/I34,"") | BG34: =+IF(SUM(AO34:AR34)>0,AO34/AN34,"") | BH34: =+IF(G34>0,K34/G34,"") | BI34: =+IF(SUM(AO34:AR34)>0,AQ34/AN34,"") | BK34: =+IF(E34>0,(AJ34/E34),"") | BL34: =+IF(E34>0,(AJ34/F34),"") | BM34: =+IF(E34>0,(AJ34/G34),"") | BN34: =+IF(E34>0,(AJ34/J34),"") | BP34: =IF(AJ34>0,(N34/AJ34),"") | BQ34: 0 | BR34: =IF(AJ34>0,(AK34/AJ34),"") | BS34: =IF(AJ34>0,(AK34/AJ34),"") | BT34: =IF(J34>0,AD34/J34,"") | BV34: =IF(AN34>0,(E34/AN34),"") | BW34: =IF(AN34>0,(G34/AN34),"") | BX34: =IF(AN34>0,(J34/AN34),"") | BY34: =IF(AN34>0,(K34/AN34),"") | BZ34: =IF(AN34>0,(AJ34/AN34),"") | CA34: =IF(AN34>0,(AK34/AN34),"") | CC34: =IFERROR(((AN34-AO34)*3600)/J34,"-") -> - | CD34: =IFERROR((AR34*3600)/J34,"-") -> - | CE34: =IFERROR((AQ34*3600)/J34,"-") -> - | CF34: =IFERROR((AO34*3600)/J34,"-") -> - | CG34: =IFERROR((AP34*3600)/J34,"-") -> -
A35: Average | C35: =AVERAGE(C4:C34) -> #DIV/0! | D35: =AVERAGE(D4:D34) -> #DIV/0! | E35: =AVERAGE(E4:E34) -> #DIV/0! | F35: =AVERAGE(F4:F34) -> #DIV/0! | G35: =AVERAGE(G4:G34) -> #DIV/0! | H35: =AVERAGE(H4:H34) -> #DIV/0! | I35: =AVERAGE(I4:I34) -> #DIV/0! | J35: =AVERAGE(J4:J34) -> #DIV/0! | ... AW35: =AVERAGE(AW4:AW34) -> #DIV/0! | AX35: =IFERROR(AN35/AW35,"-") -> - | AZ35: =IF(E35>0,F35/E35,"") -> #DIV/0! | BA35: =+IF(E35>0,G35/E35,"") -> #DIV/0! | BB35: =+IF(E35>0,AJ35/E35,"") -> #DIV/0! | BD35: =+IF(G35>0,I35/G35,"") -> #DIV/0! | BE35: =+IF(G35>0,J35/G35,"") -> #DIV/0! | BF35: =+IF(I35>0,L35/I35,"") -> #DIV/0! | BG35: =+IF(SUM(AO35:AR35)>0,AO35/AN35,"") -> #DIV/0! | BH35: =+IF(G35>0,K35/G35,"") -> #DIV/0! | BI35: =+IF(SUM(AO35:AR35)>0,AQ35/AN35,"") -> #DIV/0! | BK35: =+IF(E35>0,(AJ35/E35),"") -> #DIV/0! | BL35: =+IF(E35>0,(AJ35/F35),"") -> #DIV/0! | BM35: =+IF(E35>0,(AJ35/G35),"") -> #DIV/0! | BN35: =+IF(E35>0,(AJ35/J35),"") -> #DIV/0! | BP35: =IF(AJ35>0,(N35/AJ35),"") -> #DIV/0! | BQ35: 0 | BR35: =IF(AJ35>0,(AK35/AJ35),"") -> #DIV/0! | BS35: =IF(AJ35>0,(AK35/AJ35),"") -> #DIV/0! | BT35: =IF(J35>0,AD35/J35,"") -> #DIV/0! | BV35: =IF(AN35>0,(E35/AN35),"") -> #DIV/0! | BW35: =IF(AN35>0,(G35/AN35),"") -> #DIV/0! | BX35: =IF(AN35>0,(J35/AN35),"") -> #DIV/0! | BY35: =IF(AN35>0,(K35/AN35),"") -> #DIV/0! | BZ35: =IF(AN35>0,(AJ35/AN35),"") -> #DIV/0! | CA35: =IF(AN35>0,(AK35/AN35),"") -> #DIV/0! | CC35: =IFERROR(((AN35-AO35)*3600)/J35,"-") -> - | CD35: =IFERROR((AR35*3600)/J35,"-") -> - | CE35: =IFERROR((AQ35*3600)/J35,"-") -> - | CF35: =IFERROR((AO35*3600)/J35,"-") -> - | CG35: =IFERROR((AP35*3600)/J35,"-") -> -
A36: Total | C36: =SUM(C4:C34) -> 0 | D36: =SUM(D4:D34) -> 0 | E36: =SUM(E4:E34) -> 0 | F36: =SUM(F4:F34) -> 0 | G36: =SUM(G4:G34) -> 0 | H36: =SUM(H4:H34) -> 0 | I36: =SUM(I4:I34) -> 0 | J36: =SUM(J4:J34) -> 0 | ... AW36: =SUM(AW4:AW34) -> 0 | AX36: =IFERROR(AN36/AW36,"-") -> - | AZ36: =IF(E36>0,F36/E36,"") | BA36: =+IF(E36>0,G36/E36,"") | BB36: =+IF(E36>0,AJ36/E36,"") | BD36: =+IF(G36>0,I36/G36,"") | BE36: =+IF(G36>0,J36/G36,"") | BF36: =+IF(I36>0,L36/I36,"") | BG36: =+IF(SUM(AO36:AR36)>0,AO36/AN36,"") | BH36: =+IF(G36>0,K36/G36,"") | BI36: =+IF(SUM(AO36:AR36)>0,AQ36/AN36,"") | BK36: =+IF(E36>0,(AJ36/E36),"") | BL36: =+IF(E36>0,(AJ36/F36),"") | BM36: =+IF(E36>0,(AJ36/G36),"") | BN36: =+IF(E36>0,(AJ36/J36),"") | BP36: =IF(AJ36>0,(N36/AJ36),"") | BQ36: 0 | BR36: =IF(AJ36>0,(AK36/AJ36),"") | BS36: =IF(AJ36>0,(AK36/AJ36),"") | BT36: =IF(J36>0,AD36/J36,"") | BV36: =IF(AN36>0,(E36/AN36),"") | BW36: =IF(AN36>0,(G36/AN36),"") | BX36: =IF(AN36>0,(J36/AN36),"") | BY36: =IF(AN36>0,(K36/AN36),"") | BZ36: =IF(AN36>0,(AJ36/AN36),"") | CA36: =IF(AN36>0,(AK36/AN36),"") | CC36: =IFERROR(((AN36-AO36)*3600)/J36,"-") -> - | CD36: =IFERROR((AR36*3600)/J36,"-") -> - | CE36: =IFERROR((AQ36*3600)/J36,"-") -> - | CF36: =IFERROR((AO36*3600)/J36,"-") -> - | CG36: =IFERROR((AP36*3600)/J36,"-") -> -

Sheet EL_DEL_CD2_SBI_1_4_
A1: DIALER MIS | AZ1: Dashboard Measurements | BD1: System Efficiency | BK1: Contact Rates | BP1: Contact Termcodes | BV1: Agent Hour Statistics | CC1: Average Call time Statistics
A2: Date | B2: Day | C2: Total Accounts | D2: Accounts Excluded | E2: Accounts Scheduled | F2: Accounts Called | G2: Dials | H2: Actual Dialer Dials | I2: Answers | J2: Connects | K2: Make Calls | L2: Aborts | M2: DROP | N2: PTP | O2: PAD | P2: OTP | Q2: DISP | R2: WN | S2: NC | T2: AU | U2: VOML | V2: CT | W2: TC | X2: EWS | Y2: WS | Z2: DS | AA2: BCTP | AB2: DPTP | AC2: WH | AD2: LB | AE2: TCBL | AF2: TPC | AG2: RTP | AH2: CBL | AI2: TOTAL CALLS | AJ2: TOTAL Contacts | AK2: TOTAL Promises | AL2: Logged in Time | AM2: Not Ready Time | AN2: Time On System | AO2: Idle Time | AP2: Preview Time | AQ2: Wrap Time | AR2: Talk Time | AS2: Agent Hours | AT2: Cur_Bal | AU2: PTP Value | AV2: Total PTP Value | AW2: Count Of Agents | AX2: Average TOS | AZ2: Completion Rate | BA2: Penetration | BB2: Contact Rate | BD2: Answer Rate | BE2: Connect Rate | BF2: Abort / Answer Rate | BG2: Idle Rate | BH2: Make Call Rate | BI2: Wrap Rate | BK2: Contact / Download | BL2: Contact / Accounts called | BM2: Contact / Dial | BN2: Contact / Connect | BP2: PTP Rate | BQ2: Pick-Up Rate | BR2: PTP+PAD rate | BS2: CallBack Rate | BT2: LB Rate | BV2: Accounts per Hour | BW2: Dials per Hour | BX2: Connects per Hour | BY2: Make Call per Hour | BZ2: Contacts per Hour | CA2: Promises per Hour | CC2: AHT | CD2: Talk | CE2: Wrap | CF2: Idle | CG2: Preview
AX3: Count Of Agents
A4: =EL_DEL_CD2_JO_!A4 -> 46296 | B4: =+TEXT(A4,"DDD") -> Thu | AX4: =IFERROR(AN4/AW4,"-") -> - | AZ4: =IF(E4>0,F4/E4,"") | BA4: =+IF(E4>0,G4/E4,"") | BB4: =+IF(E4>0,AJ4/E4,"") | BD4: =+IF(G4>0,I4/G4,"") | BE4: =+IF(G4>0,J4/G4,"") | BF4: =+IF(I4>0,L4/I4,"") | BG4: =+IF(SUM(AO4:AR4)>0,AO4/AN4,"") | BH4: =+IF(G4>0,K4/G4,"") | BI4: =+IF(SUM(AO4:AR4)>0,AQ4/AN4,"") | BK4: =+IF(E4>0,(AJ4/E4),"") | BL4: =+IF(E4>0,(AJ4/F4),"") | BM4: =+IF(E4>0,(AJ4/G4),"") | BN4: =+IF(E4>0,(AJ4/J4),"") | BP4: =IF(AJ4>0,(N4/AJ4),"") | BQ4: 0 | BR4: =IF(AJ4>0,(AK4/AJ4),"") | BS4: =IF(AJ4>0,(AK4/AJ4),"") | BT4: =IF(J4>0,AD4/J4,"") | BV4: =IF(AN4>0,(E4/AN4),"") | BW4: =IF(AN4>0,(G4/AN4),"") | BX4: =IF(AN4>0,(J4/AN4),"") | BY4: =IF(AN4>0,(K4/AN4),"") | BZ4: =IF(AN4>0,(AJ4/AN4),"") | CA4: =IF(AN4>0,(AK4/AN4),"") | CC4: =IFERROR(((AN4-AO4)*3600)/J4,"-") -> - | CD4: =IFERROR((AR4*3600)/J4,"-") -> - | CE4: =IFERROR((AQ4*3600)/J4,"-") -> - | CF4: =IFERROR((AO4*3600)/J4,"-") -> - | CG4: =IFERROR((AP4*3600)/J4,"-") -> -
A5: =EL_DEL_CD2_JO_!A5 -> 46297 | B5: =+TEXT(A5,"DDD") -> Fri | AX5: =IFERROR(AN5/AW5,"-") -> - | AZ5: =IF(E5>0,F5/E5,"") | BA5: =+IF(E5>0,G5/E5,"") | BB5: =+IF(E5>0,AJ5/E5,"") | BD5: =+IF(G5>0,I5/G5,"") | BE5: =+IF(G5>0,J5/G5,"") | BF5: =+IF(I5>0,L5/I5,"") | BG5: =+IF(SUM(AO5:AR5)>0,AO5/AN5,"") | BH5: =+IF(G5>0,K5/G5,"") | BI5: =+IF(SUM(AO5:AR5)>0,AQ5/AN5,"") | BK5: =+IF(E5>0,(AJ5/E5),"") | BL5: =+IF(E5>0,(AJ5/F5),"") | BM5: =+IF(E5>0,(AJ5/G5),"") | BN5: =+IF(E5>0,(AJ5/J5),"") | BP5: =IF(AJ5>0,(N5/AJ5),"") | BQ5: 0 | BR5: =IF(AJ5>0,(AK5/AJ5),"") | BS5: =IF(AJ5>0,(AK5/AJ5),"") | BT5: =IF(J5>0,AD5/J5,"") | BV5: =IF(AN5>0,(E5/AN5),"") | BW5: =IF(AN5>0,(G5/AN5),"") | BX5: =IF(AN5>0,(J5/AN5),"") | BY5: =IF(AN5>0,(K5/AN5),"") | BZ5: =IF(AN5>0,(AJ5/AN5),"") | CA5: =IF(AN5>0,(AK5/AN5),"") | CC5: =IFERROR(((AN5-AO5)*3600)/J5,"-") -> - | CD5: =IFERROR((AR5*3600)/J5,"-") -> - | CE5: =IFERROR((AQ5*3600)/J5,"-") -> - | CF5: =IFERROR((AO5*3600)/J5,"-") -> - | CG5: =IFERROR((AP5*3600)/J5,"-") -> -
A6: =EL_DEL_CD2_JO_!A6 -> 46298 | B6: =+TEXT(A6,"DDD") -> Sat | AX6: =IFERROR(AN6/AW6,"-") -> - | AZ6: =IF(E6>0,F6/E6,"") | BA6: =+IF(E6>0,G6/E6,"") | BB6: =+IF(E6>0,AJ6/E6,"") | BD6: =+IF(G6>0,I6/G6,"") | BE6: =+IF(G6>0,J6/G6,"") | BF6: =+IF(I6>0,L6/I6,"") | BG6: =+IF(SUM(AO6:AR6)>0,AO6/AN6,"") | BH6: =+IF(G6>0,K6/G6,"") | BI6: =+IF(SUM(AO6:AR6)>0,AQ6/AN6,"") | BK6: =+IF(E6>0,(AJ6/E6),"") | BL6: =+IF(E6>0,(AJ6/F6),"") | BM6: =+IF(E6>0,(AJ6/G6),"") | BN6: =+IF(E6>0,(AJ6/J6),"") | BP6: =IF(AJ6>0,(N6/AJ6),"") | BQ6: 0 | BR6: =IF(AJ6>0,(AK6/AJ6),"") | BS6: =IF(AJ6>0,(AK6/AJ6),"") | BT6: =IF(J6>0,AD6/J6,"") | BV6: =IF(AN6>0,(E6/AN6),"") | BW6: =IF(AN6>0,(G6/AN6),"") | BX6: =IF(AN6>0,(J6/AN6),"") | BY6: =IF(AN6>0,(K6/AN6),"") | BZ6: =IF(AN6>0,(AJ6/AN6),"") | CA6: =IF(AN6>0,(AK6/AN6),"") | CC6: =IFERROR(((AN6-AO6)*3600)/J6,"-") -> - | CD6: =IFERROR((AR6*3600)/J6,"-") -> - | CE6: =IFERROR((AQ6*3600)/J6,"-") -> - | CF6: =IFERROR((AO6*3600)/J6,"-") -> - | CG6: =IFERROR((AP6*3600)/J6,"-") -> -
A7: =EL_DEL_CD2_JO_!A7 -> 46299 | B7: =+TEXT(A7,"DDD") -> Sun | AX7: =IFERROR(AN7/AW7,"-") -> - | AZ7: =IF(E7>0,F7/E7,"") | BA7: =+IF(E7>0,G7/E7,"") | BB7: =+IF(E7>0,AJ7/E7,"") | BD7: =+IF(G7>0,I7/G7,"") | BE7: =+IF(G7>0,J7/G7,"") | BF7: =+IF(I7>0,L7/I7,"") | BG7: =+IF(SUM(AO7:AR7)>0,AO7/AN7,"") | BH7: =+IF(G7>0,K7/G7,"") | BI7: =+IF(SUM(AO7:AR7)>0,AQ7/AN7,"") | BK7: =+IF(E7>0,(AJ7/E7),"") | BL7: =+IF(E7>0,(AJ7/F7),"") | BM7: =+IF(E7>0,(AJ7/G7),"") | BN7: =+IF(E7>0,(AJ7/J7),"") | BP7: =IF(AJ7>0,(N7/AJ7),"") | BQ7: 0 | BR7: =IF(AJ7>0,(AK7/AJ7),"") | BS7: =IF(AJ7>0,(AK7/AJ7),"") | BT7: =IF(J7>0,AD7/J7,"") | BV7: =IF(AN7>0,(E7/AN7),"") | BW7: =IF(AN7>0,(G7/AN7),"") | BX7: =IF(AN7>0,(J7/AN7),"") | BY7: =IF(AN7>0,(K7/AN7),"") | BZ7: =IF(AN7>0,(AJ7/AN7),"") | CA7: =IF(AN7>0,(AK7/AN7),"") | CC7: =IFERROR(((AN7-AO7)*3600)/J7,"-") -> - | CD7: =IFERROR((AR7*3600)/J7,"-") -> - | CE7: =IFERROR((AQ7*3600)/J7,"-") -> - | CF7: =IFERROR((AO7*3600)/J7,"-") -> - | CG7: =IFERROR((AP7*3600)/J7,"-") -> -
A8: =EL_DEL_CD2_JO_!A8 -> 46300 | B8: =+TEXT(A8,"DDD") -> Mon | AX8: =IFERROR(AN8/AW8,"-") -> - | AZ8: =IF(E8>0,F8/E8,"") | BA8: =+IF(E8>0,G8/E8,"") | BB8: =+IF(E8>0,AJ8/E8,"") | BD8: =+IF(G8>0,I8/G8,"") | BE8: =+IF(G8>0,J8/G8,"") | BF8: =+IF(I8>0,L8/I8,"") | BG8: =+IF(SUM(AO8:AR8)>0,AO8/AN8,"") | BH8: =+IF(G8>0,K8/G8,"") | BI8: =+IF(SUM(AO8:AR8)>0,AQ8/AN8,"") | BK8: =+IF(E8>0,(AJ8/E8),"") | BL8: =+IF(E8>0,(AJ8/F8),"") | BM8: =+IF(E8>0,(AJ8/G8),"") | BN8: =+IF(E8>0,(AJ8/J8),"") | BP8: =IF(AJ8>0,(N8/AJ8),"") | BQ8: 0 | BR8: =IF(AJ8>0,(AK8/AJ8),"") | BS8: =IF(AJ8>0,(AK8/AJ8),"") | BT8: =IF(J8>0,AD8/J8,"") | BV8: =IF(AN8>0,(E8/AN8),"") | BW8: =IF(AN8>0,(G8/AN8),"") | BX8: =IF(AN8>0,(J8/AN8),"") | BY8: =IF(AN8>0,(K8/AN8),"") | BZ8: =IF(AN8>0,(AJ8/AN8),"") | CA8: =IF(AN8>0,(AK8/AN8),"") | CC8: =IFERROR(((AN8-AO8)*3600)/J8,"-") -> - | CD8: =IFERROR((AR8*3600)/J8,"-") -> - | CE8: =IFERROR((AQ8*3600)/J8,"-") -> - | CF8: =IFERROR((AO8*3600)/J8,"-") -> - | CG8: =IFERROR((AP8*3600)/J8,"-") -> -
A9: =EL_DEL_CD2_JO_!A9 -> 46301 | B9: =+TEXT(A9,"DDD") -> Tue | AX9: =IFERROR(AN9/AW9,"-") -> - | AZ9: =IF(E9>0,F9/E9,"") | BA9: =+IF(E9>0,G9/E9,"") | BB9: =+IF(E9>0,AJ9/E9,"") | BD9: =+IF(G9>0,I9/G9,"") | BE9: =+IF(G9>0,J9/G9,"") | BF9: =+IF(I9>0,L9/I9,"") | BG9: =+IF(SUM(AO9:AR9)>0,AO9/AN9,"") | BH9: =+IF(G9>0,K9/G9,"") | BI9: =+IF(SUM(AO9:AR9)>0,AQ9/AN9,"") | BK9: =+IF(E9>0,(AJ9/E9),"") | BL9: =+IF(E9>0,(AJ9/F9),"") | BM9: =+IF(E9>0,(AJ9/G9),"") | BN9: =+IF(E9>0,(AJ9/J9),"") | BP9: =IF(AJ9>0,(N9/AJ9),"") | BQ9: 0 | BR9: =IF(AJ9>0,(AK9/AJ9),"") | BS9: =IF(AJ9>0,(AK9/AJ9),"") | BT9: =IF(J9>0,AD9/J9,"") | BV9: =IF(AN9>0,(E9/AN9),"") | BW9: =IF(AN9>0,(G9/AN9),"") | BX9: =IF(AN9>0,(J9/AN9),"") | BY9: =IF(AN9>0,(K9/AN9),"") | BZ9: =IF(AN9>0,(AJ9/AN9),"") | CA9: =IF(AN9>0,(AK9/AN9),"") | CC9: =IFERROR(((AN9-AO9)*3600)/J9,"-") -> - | CD9: =IFERROR((AR9*3600)/J9,"-") -> - | CE9: =IFERROR((AQ9*3600)/J9,"-") -> - | CF9: =IFERROR((AO9*3600)/J9,"-") -> - | CG9: =IFERROR((AP9*3600)/J9,"-") -> -
